Workbook

Sheet 购物零售方案123
A1: 2023 | B1: 销售 | C1: 利润 | D1: 参考毛利率 | E1: 销售占比 | F1: 利润占比 | H1: 2024 | I1: 销售 | J1: 利润 | K1: 参考毛利率 | L1: 销售占比 | M1: 利润占比 | N1: 销售同比 | O1: 利润同比 | Q1: 2024实际 | R1: 销售 | S1: 利润 | T1: 参考毛利率 | U1: 销售占比 | V1: 利润占比 | W1: 销售同比 | X1: 利润同比 | Y1: * 方案一： 财务底线预测 | Z1: 2025购物零售 (含本地生活) | AA1: 销售 | AB1: 利润 | AC1: 参考毛利率 | AD1: 销售占比 | AE1: 利润占比 | AF1: 销售同比 | AG1: 利润同比24年实际 | AH1: * 方案二： 控制降幅 | AI1: 2025 | AJ1: 销售 | AK1: 利润 | AL1: 参考毛利率 | AM1: 销售占比 | AN1: 利润占比 （年度权重64开） | AO1: 销售同比 | AP1: 利润同比
A2: 1月 | B2: 2.1462181e+08 | C2: 48124681 | D2: =C2*1.12/B2 -> 0.25113777 | E2: =B2/$B$14 -> 0.11008355 | F2: =C2/$C$14 -> 0.11846536 | H2: 1月 | I2: 1.6722146e+08 | J2: 34006764 | K2: =J2*1.12/I2 -> 0.22776728 | L2: =I2/$I$14 -> 0.12602766 | M2: =J2/$J$14 -> 0.11329782 | N2: =I2/B2-1 -> -0.22085525 | O2: =J2/C2-1 -> -0.29336126 | Q2: 1月 | R2: 1.6722146e+08 | S2: 34006764 | T2: =S2*1.12/R2 -> 0.22776728 | U2: =R2/$R$14 -> 0.12637179 | V2: =S2/$S$14 -> 0.11364594 | W2: =R2/B2-1 -> -0.22085525 | X2: =S2/C2-1 -> -0.29336126 | Z2: 1月 | AA2: =AB2*1.12/AC2 -> 1.0672287e+08 | AB2: 26403676 | AC2: 0.2770926 | AD2: =AA2/$AA$14 -> 0.11479197 | AE2: 0.11557371 | AF2: =AA2/I2-1 -> -0.36178722 | AG2: =AB2/S2-1 -> -0.22357575 | AI2: 1月 | AJ2: =AM2*$AJ$14 -> 1.2144924e+08 | AK2: 27381363 | AL2: 0.2770926 | AM2: 0.12598268 | AN2: 0.11557371 | AO2: =AJ2/R2-1 -> -0.27372213 | AP2: =AK2/S2-1 -> -0.19482596
A3: 2月 | B3: 1.5226345e+08 | C3: 30883670 | D3: =C3*1.12/B3 -> 0.22717014 | E3: =B3/$B$14 -> 0.078098781 | F3: =C3/$C$14 -> 0.076024295 | H3: 2月 | I3: 1.093038e+08 | J3: 23684768 | K3: =J3*1.12/I3 -> 0.24269001 | L3: =I3/$I$14 -> 0.082377599 | M3: =J3/$J$14 -> 0.078908787 | N3: =I3/B3-1 -> -0.28214028 | O3: =J3/C3-1 -> -0.23309736 | Q3: 2月 | R3: 1.093038e+08 | S3: 23684768 | T3: =S3*1.12/R3 -> 0.24269001 | U3: =R3/$R$14 -> 0.082602538 | V3: =S3/$S$14 -> 0.079151245 | W3: =R3/B3-1 -> -0.28214028 | X3: =S3/C3-1 -> -0.23309736 | Z3: 2月 | AA3: =AB3*1.12/AC3 -> 73034628 | AB3: 17651897 | AC3: 0.27069522 | AD3: =AA3/$AA$14 -> 0.078556631 | AE3: 0.077900465 | AF3: =AA3/I3-1 -> -0.33181985 | AG3: =AB3/S3-1 -> -0.25471522 | AI3: 2月 | AJ3: =AM3*$AJ$14 -> 79534596 | AK3: 18305519 | AL3: 0.27069522 | AM3: 0.082503448 | AN3: 0.077900465 | AO3: =AJ3/R3-1 -> -0.27235286 | AP3: =AK3/S3-1 -> -0.22711848
A4: 3月 | B4: 1.6175068e+08 | C4: 33760031 | D4: =C4*1.12/B4 -> 0.23376245 | E4: =B4/$B$14 -> 0.082964959 | F4: =C4/$C$14 -> 0.083104843 | H4: 3月 | I4: 1.1619973e+08 | J4: 25054034 | K4: =J4*1.12/I4 -> 0.24148523 | L4: =I4/$I$14 -> 0.087574766 | M4: =J4/$J$14 -> 0.083470668 | N4: =I4/B4-1 -> -0.28161212 | O4: =J4/C4-1 -> -0.25787883 | Q4: 3月 | R4: 1.1619973e+08 | S4: 25054034 | T4: =S4*1.12/R4 -> 0.24148523 | U4: =R4/$R$14 -> 0.087813896 | V4: =S4/$S$14 -> 0.083727143 | W4: =R4/B4-1 -> -0.28161212 | X4: =S4/C4-1 -> -0.25787883 | Z4: 3月 | AA4: =AB4*1.12/AC4 -> 77033742 | AB4: 18977869 | AC4: 0.27592082 | AD4: =AA4/$AA$14 -> 0.082858109 | AE4: 0.083478223 | AF4: =AA4/I4-1 -> -0.33705747 | AG4: =AB4/S4-1 -> -0.24252241 | AI4: 3月 | AJ4: =AM4*$AJ$14 -> 87237230 | AK4: 19680590 | AL4: 0.27592082 | AM4: 0.090493605 | AN4: 0.083478223 | AO4: =AJ4/R4-1 -> -0.24924755 | AP4: =AK4/S4-1 -> -0.21447419
A5: 4月 | B5: 1.8408006e+08 | C5: 34204404 | D5: =C5*1.12/B5 -> 0.20811017 | E5: =B5/$B$14 -> 0.094418117 | F5: =C5/$C$14 -> 0.084198728 | H5: 4月 | I5: 1.1157144e+08 | J5: 24919117 | K5: =J5*1.12/I5 -> 0.25014834 | L5: =I5/$I$14 -> 0.084086625 | M5: =J5/$J$14 -> 0.083021177 | N5: =I5/B5-1 -> -0.39389718 | O5: =J5/C5-1 -> -0.27146467 | Q5: 4月 | R5: 1.1157144e+08 | S5: 24919117 | T5: =S5*1.12/R5 -> 0.25014834 | U5: =R5/$R$14 -> 0.084316231 | V5: =S5/$S$14 -> 0.083276271 | W5: =R5/B5-1 -> -0.39389718 | X5: =S5/C5-1 -> -0.27146467 | Z5: 4月 | AA5: =AB5*1.12/AC5 -> 74747016 | AB5: 19051014 | AC5: 0.28545803 | AD5: =AA5/$AA$14 -> 0.080398488 | AE5: 0.083645254 | AF5: =AA5/I5-1 -> -0.33005244 | AG5: =AB5/S5-1 -> -0.23548598 | AI5: 4月 | AJ5: =AM5*$AJ$14 -> 76438412 | AK5: 19756444 | AL5: 0.28545803 | AM5: 0.07929169 | AN5: 0.083645254 | AO5: =AJ5/R5-1 -> -0.31489268 | AP5: =AK5/S5-1 -> -0.20717721
A6: 5月 | B6: 1.529621e+08 | C6: 31976609 | D6: =C6*1.12/B6 -> 0.23413514 | E6: =B6/$B$14 -> 0.07845713 | F6: =C6/$C$14 -> 0.078714711 | H6: 5月 | I6: 99069605 | J6: 22040447 | K6: =J6*1.12/I6 -> 0.24917128 | L6: =I6/$I$14 -> 0.074664525 | M6: =J6/$J$14 -> 0.073430525 | N6: =I6/B6-1 -> -0.35232579 | O6: =J6/C6-1 -> -0.31073219 | Q6: 5月 | R6: 99069605 | S6: 22040447 | T6: =S6*1.12/R6 -> 0.24917128 | U6: =R6/$R$14 -> 0.074868402 | V6: =S6/$S$14 -> 0.073656151 | W6: =R6/B6-1 -> -0.35232579 | X6: =S6/C6-1 -> -0.31073219 | Z6: 5月 | AA6: =AB6*1.12/AC6 -> 75825989 | AB6: 17332853 | AC6: 0.25601769 | AD6: =AA6/$AA$14 -> 0.081559041 | AE6: 0.075679575 | AF6: =AA6/I6-1 -> -0.23461904 | AG6: =AB6/S6-1 -> -0.21358888 | AI6: 5月 | AJ6: =AM6*$AJ$14 -> 75827612 | AK6: 17974661 | AL6: 0.25601769 | AM6: 0.07865809 | AN6: 0.075679575 | AO6: =AJ6/R6-1 -> -0.23460266 | AP6: =AK6/S6-1 -> -0.1844693
A7: 6月 | B7: 1.4523334e+08 | C7: 31037674 | D7: =C7*1.12/B7 -> 0.23935409 | E7: =B7/$B$14 -> 0.074492906 | F7: =C7/$C$14 -> 0.076403396 | H7: 6月 | I7: 99516460 | J7: 22879456 | K7: =J7*1.12/I7 -> 0.25749499 | L7: =I7/$I$14 -> 0.0750013 | M7: =J7/$J$14 -> 0.076225787 | N7: =I7/B7-1 -> -0.31478227 | O7: =J7/C7-1 -> -0.2628489 | Q7: 6月 | R7: 99516460 | S7: 22879456 | T7: =S7*1.12/R7 -> 0.25749499 | U7: =R7/$R$14 -> 0.075206097 | V7: =S7/$S$14 -> 0.076460002 | W7: =R7/B7-1 -> -0.31478227 | X7: =S7/C7-1 -> -0.2628489 | Z7: 6月 | AA7: =AB7*1.12/AC7 -> 71544978 | AB7: 17388881 | AC7: 0.27221403 | AD7: =AA7/$AA$14 -> 0.076954351 | AE7: 0.07643736 | AF7: =AA7/I7-1 -> -0.28107392 | AG7: =AB7/S7-1 -> -0.23997838 | AI7: 6月 | AJ7: =AM7*$AJ$14 -> 71670920 | AK7: 18032764 | AL7: 0.27221403 | AM7: 0.074346238 | AN7: 0.07643736 | AO7: =AJ7/R7-1 -> -0.27980838 | AP7: =AK7/S7-1 -> -0.21183596
A8: 7月 | B8: 1.3255032e+08 | C8: 28669117 | D8: =C8*1.12/B8 -> 0.24224318 | E8: =B8/$B$14 -> 0.067987547 | F8: =C8/$C$14 -> 0.070572877 | H8: 7月 | I8: 96727683 | J8: 21936037 | K8: =J8*1.12/I8 -> 0.25399515 | L8: =I8/$I$14 -> 0.072899518 | M8: =J8/$J$14 -> 0.073082671 | N8: =I8/B8-1 -> -0.2702569 | O8: =J8/C8-1 -> -0.23485481 | Q8: 7月 | R8: 96727683 | S8: 21936037 | T8: =S8*1.12/R8 -> 0.25399515 | U8: =R8/$R$14 -> 0.073098576 | V8: =S8/$S$14 -> 0.073307228 | W8: =R8/B8-1 -> -0.2702569 | X8: =S8/C8-1 -> -0.23485481 | Z8: 7月 | AA8: =AB8*1.12/AC8 -> 68837414 | AB8: 16366992 | AC8: 0.26629459 | AD8: =AA8/$AA$14 -> 0.074042073 | AE8: 0.072213487 | AF8: =AA8/I8-1 -> -0.28833802 | AG8: =AB8/S8-1 -> -0.25387655 | AI8: 7月 | AJ8: =AM8*$AJ$14 -> 69915671 | AK8: 16973036 | AL8: 0.26629459 | AM8: 0.07252547 | AN8: 0.072213487 | AO8: =AJ8/R8-1 -> -0.27719067 | AP8: =AK8/S8-1 -> -0.22624876
A9: 8月 | B9: 1.3821707e+08 | C9: 30480858 | D9: =C9*1.12/B9 -> 0.24699236 | E9: =B9/$B$14 -> 0.070894132 | F9: =C9/$C$14 -> 0.07503272 | H9: 8月 | I9: 93524294 | J9: 21669839 | K9: =J9*1.12/I9 -> 0.25950711 | L9: =I9/$I$14 -> 0.070485261 | M9: =J9/$J$14 -> 0.072195797 | N9: =I9/B9-1 -> -0.3233521 | O9: =J9/C9-1 -> -0.2890673 | Q9: 8月 | R9: 93524294 | S9: 21669839 | T9: =S9*1.12/R9 -> 0.25950711 | U9: =R9/$R$14 -> 0.070677727 | V9: =S9/$S$14 -> 0.072417629 | W9: =R9/B9-1 -> -0.3233521 | X9: =S9/C9-1 -> -0.2890673 | Z9: 8月 | AA9: =AB9*1.12/AC9 -> 70401539 | AB9: 16773123 | AC9: 0.2668393 | AD9: =AA9/$AA$14 -> 0.075724459 | AE9: 0.073463665 | AF9: =AA9/I9-1 -> -0.24723795 | AG9: =AB9/S9-1 -> -0.2259692 | AI9: 8月 | AJ9: =AM9*$AJ$14 -> 71215317 | AK9: 17394206 | AL9: 0.2668393 | AM9: 0.073873628 | AN9: 0.073463665 | AO9: =AJ9/R9-1 -> -0.23853671 | AP9: =AK9/S9-1 -> -0.19730804
A10: 9月 | B10: 1.5463191e+08 | C10: 30993082 | D10: =C10*1.12/B10 -> 0.22448312 | E10: =B10/$B$14 -> 0.079313607 | F10: =C10/$C$14 -> 0.076293629 | H10: 9月 | I10: 96919381 | J10: 22210990 | K10: =J10*1.12/I10 -> 0.25667012 | L10: =I10/$I$14 -> 0.073043993 | M10: =J10/$J$14 -> 0.073998712 | N10: =I10/B10-1 -> -0.37322521 | O10: =J10/C10-1 -> -0.28335652 | Q10: 9月 | R10: 96919381 | S10: 22210990 | T10: =S10*1.12/R10 -> 0.25667012 | U10: =R10/$R$14 -> 0.073243445 | V10: =S10/$S$14 -> 0.074226084 | W10: =R10/B10-1 -> -0.37322521 | X10: =S10/C10-1 -> -0.28335652 | Z10: 9月 | AA10: =AB10*1.12/AC10 -> 68489876 | AB10: 17122276 | AC10: 0.27999685 | AD10: =AA10/$AA$14 -> 0.073668259 | AE10: 0.075053102 | AF10: =AA10/I10-1 -> -0.29333147 | AG10: =AB10/S10-1 -> -0.22910794 | AI10: 9月 | AJ10: =AM10*$AJ$14 -> 69054266 | AK10: 17756288 | AL10: 0.27999685 | AM10: 0.071631911 | AN10: 0.075053102 | AO10: =AJ10/R10-1 -> -0.28750818 | AP10: =AK10/S10-1 -> -0.200563
A11: 10月 | B11: 1.4214851e+08 | C11: 30396484 | D11: =C11*1.12/B11 -> 0.23949645 | E11: =B11/$B$14 -> 0.072910636 | F11: =C11/$C$14 -> 0.074825022 | H11: 10月 | I11: 106250450 | J11: 23889521 | K11: =J11*1.12/I11 -> 0.25182259 | L11: =I11/$I$14 -> 0.080076421 | M11: =J11/$J$14 -> 0.079590948 | N11: =I11/B11-1 -> -0.2525391 | O11: =J11/C11-1 -> -0.2140696 | Q11: 10月 | R11: 106250450 | S11: 23889521 | T11: =S11*1.12/R11 -> 0.25182259 | U11: =R11/$R$14 -> 0.080295076 | V11: =S11/$S$14 -> 0.079835502 | W11: =R11/B11-1 -> -0.2525391 | X11: =S11/C11-1 -> -0.2140696 | Z11: 10月 | AA11: =AB11*1.12/AC11 -> 73382319 | AB11: 17593312 | AC11: 0.26851848 | AD11: =AA11/$AA$14 -> 0.07893061 | AE11: 0.07783131 | AF11: =AA11/I11-1 -> -0.3093458 | AG11: =AB11/S11-1 -> -0.26355527 | AI11: 10月 | AJ11: =AM11*$AJ$14 -> 74258175 | AK11: 18244765 | AL11: 0.26851848 | AM11: 0.07703007 | AN11: 0.07783131 | AO11: =AJ11/R11-1 -> -0.30110249 | AP11: =AK11/S11-1 -> -0.23628587
A12: 11月 | B12: 1.9186272e+08 | C12: 38054014 | D12: =C12*1.12/B12 -> 0.22214058 | E12: =B12/$B$14 -> 0.09840999 | F12: =C12/$C$14 -> 0.093675057 | H12: 11月 | I12: 117875870 | J12: 29188984 | K12: =J12*1.12/I12 -> 0.27733973 | L12: =I12/$I$14 -> 0.088838003 | M12: =J12/$J$14 -> 0.097246776 | N12: =I12/B12-1 -> -0.3856239 | O12: =J12/C12-1 -> -0.23295912 | Q12: 11月 | R12: 117875870 | S12: 29188984 | T12: =S12*1.12/R12 -> 0.27733973 | U12: =R12/$R$14 -> 0.089080582 | V12: =S12/$S$14 -> 0.097545581 | W12: =R12/B12-1 -> -0.3856239 | X12: =S12/C12-1 -> -0.23295912 | Z12: 11月 | AA12: =AB12*1.12/AC12 -> 84302979 | AB12: 22076337 | AC12: 0.29329329 | AD12: =AA12/$AA$14 -> 0.090676959 | AE12: 0.095997371 | AF12: =AA12/I12-1 -> -0.28481564 | AG12: =AB12/S12-1 -> -0.24367572 | AI12: 11月 | AJ12: =AM12*$AJ$14 -> 84972736 | AK12: 22893790 | AL12: 0.29329329 | AM12: 0.088144582 | AN12: 0.095997371 | AO12: =AJ12/R12-1 -> -0.27913375 | AP12: =AK12/S12-1 -> -0.21567021
A13: 12月 | B13: 1.793045e+08 | C13: 37653592 | D13: =C13*1.12/B13 -> 0.2351978 | E13: =B13/$B$14 -> 0.091968641 | F13: =C13/$C$14 -> 0.092689367 | G13: * 12月财务底线 | H13: 12月 | I13: =J13*1.12/K13 -> 1.1268296e+08 | J13: 28673788 | K13: 0.285 | L13: =I13/$I$14 -> 0.084924326 | M13: =J13/$J$14 -> 0.095530336 | N13: =I13/B13-1 -> -0.37155532 | O13: =J13/C13-1 -> -0.23848466 | P13: * 12月业务预测 | Q13: 12月 | R13: =S13*1.12/T13 -> 1.0906972e+08 | S13: 27754349 | T13: 0.285 | U13: =R13/$R$14 -> 0.082425641 | V13: =S13/$S$14 -> 0.092751226 | W13: =R13/B13-1 -> -0.39170672 | X13: =S13/C13-1 -> -0.26290304 | Z13: 12月 | AA13: =AB13*1.12/AC13 -> 85383380 | AB13: 21793176 | AC13: 0.28586778 | AD13: =AA13/$AA$14 -> 0.091839047 | AE13: 0.092726482 | AF13: =AA13/I13-1 -> -0.24226891 | AG13: =AB13/S13-1 -> -0.21478336 | AI13: 12月 | AJ13: =AM13*$AJ$14 -> 82441239 | AK13: 22600144 | AL13: 0.28586778 | AM13: 0.08551859 | AN13: 0.092726482 | AO13: =AJ13/R13-1 -> -0.24414183 | AP13: =AK13/S13-1 -> -0.18570801
A14: 合计 | B14: =SUM(B2:B13) -> 1.9496265e+09 | C14: =SUM(C2:C13) -> 4.0623422e+08 | D14: =C14*1.12/B14 -> 0.23336897 | E14: =B14/$B$14 -> 1 | F14: =C14/$C$14 -> 1 | H14: 合计 | I14: =SUM(I2:I13) -> 1.3268631e+09 | J14: =SUM(J2:J13) -> 3.0015374e+08 | K14: =J14*1.12/I14 -> 0.25335861 | L14: =I14/$I$14 -> 1 | M14: =J14/$J$14 -> 1 | N14: =I14/B14-1 -> -0.319427 | O14: =J14/C14-1 -> -0.26113131 | Q14: 合计 | R14: =SUM(R2:R13) -> 1.3232499e+09 | S14: =SUM(S2:S13) -> 2.992343e+08 | T14: =S14*1.12/R14 -> 0.25327221 | U14: =R14/$R$14 -> 1 | V14: =S14/$S$14 -> 1 | W14: =R14/B14-1 -> -0.3212803 | X14: =S14/C14-1 -> -0.26339463 | Z14: 合计 | AA14: =SUM(AA2:AA13) -> 9.2970673e+08 | AB14: =AB15*AE15 -> 2.2853141e+08 | AC14: =AB14*1.12/AA14 -> 0.27530743 | AD14: =AA14/$AA$14 -> 1 | AE14: =AB14/$AB$14 -> 1 | AF14: =AA14/I14-1 -> -0.29931979 | AG14: =AB14/S14-1 -> -0.23627939 | AI14: 合计 | AJ14: =AK14*1.12/AL14 -> 9.6401542e+08 | AK14: =S14*(1-0.208) -> 2.3699357e+08 | AL14: 0.27534082 | AM14: 1 | AN14: 1 | AO14: =AJ14/R14-1 -> -0.27147893 | AP14: =AK14/S14-1 -> -0.208
Q15: 12月实际预测低于底限 | Z15: 报OPG P1利润 | AB15: 2.4497346e+08 | AE15: 0.93288231 | AI15: 计划P1目标 | AK15: 2.5404445e+08 | AN15: =AK14/AK15 -> 0.93288231 | AP15: 同比降幅控制 | AQ15: =AK15/AB15-1 -> 0.037028449
A16: 本页所有口径：购物零售+本地生活 | H16: 底限11月 | J16: 29656000 | Z16: * 25年春节放假期间：1.28-2.4；本页所有口径：购物零售+本地生活 | AK16: 自营旅游折返30万利润 | AL16: =AK15/365 -> 696012.18
H17: 底限12月 | J17: 29167000 | Z17: 注：购物零售2025年利润底限，以2024年度”购物零售+本地生活“占P1比重（ 93.3%）推算；2024年旅行社下“本地生活类”（消费服务不含住宿）利润额364万；
AB18: =AB15/365 -> 671160.16 | AH18: 方案二思路： | AI18: 1. 购物零售24年实际利润同比↓ 26.3%，考虑大屏直播有效时长，2024年导流类/东方荟普通商品/汽车等占比6.2%、电视商品贡献占比88%，时长因素影响5.5个百分点，取 -20.8%作为25年预估降幅；
AI19: 2. 25年分月利润比重按24年权重60%，23年权重40%计算；
Y20: 目标区间上限 | AB20: =AB21/365 -> 738276.18 | AI20: 3. 25年毛利率按 27.5%计；25年分月销售额按毛利率反推；
Z21: 参考：底限↑ 10% | AB21: =AB15*1.1 -> 2.6947081e+08
Z22: 参考：2023年上报OPG版，日均利润额147.8万；目标方案取高，日均170万，年中调整到165万（业务板块间调整），较财务底限上调11.6%-15%；
Z24: 参考：2024年实际 ↓10% | AB24: =S14*0.9 -> 2.6931087e+08
Z25: 参考：2024年目标框定：TV电视商品下降15%、IC电商商品增长10%，购物零售较2023年实际合计下降12%；
Z27: 财务底限目标P1，同比24年实际业绩，降幅24.0%

Sheet 0. 方案
B1: 2026年目标分解初步方案（拟）
B2: 存量整体 = 仅电视端及APP业务（含自营业务）+ 数据库营销 + 私域整体；
B4: 一、目标分解思路
B5: （一）基本规则：
B6: 1.为确保公司整体目标的达成进度，各渠道均参考历史月度比重，避免将目标重心全部分摊到下半年，减少公司风险。
B7: 2.复盘2025年度各渠道目标执行情况
B8: 存量整体、电视商品、数据库营销上半年占比均超50%（51%-55%），私域整体及第三方上半年占比43%、46%。 下半年目标比重过高，易导致滚动目标失效，最终缺口难以统筹完成。因此，在考虑业务趋势或成长性的同时，需重点优化上下半年目标的合理比重。
B9: 3.从存量整体角度，盘点2023-2025近三年的月度趋势，按1:2:3（即：17%：33%：50%）的权重，初步形成整体的月度目标分配，用于校验分渠道目标之和。
B10: 4.按存量整体趋势的客观分配，上半年占比51.4%；依据分渠道规则设定的目标，上半年合计占比51.3%；两种方案比重趋势吻合。
B12: （二）分渠道规则：
B13: 1. 仅电视端及APP业务（含自营业务）：同比下降9%左右，具体降幅与实际完成情况相关。
B14: 考虑业务结构的相似性与可参考性，2026年目标分配主要参考2025各月占比；
... B32: 4. 业务非常规举措版是在以上基础逻辑之上，再加上业务预计实施非常规举措后可额外提升的利润。
B35: 利润目标 | C35: 1月 | D35: 2月 | E35: 3月 | F35: Q1
B36: 存量整体 | C36: 23226681 | D36: 16184643 | E36: 18883028 | F36: 58294352
B37: 仅电视端及APP业务 （含自营业务） | C37: 19601681 | D37: 13951219 | E37: 15859315 | F37: 49412216
B38: 数据库营销 | C38: 2850000 | D38: 1600000 | E38: 2200000 | F38: 6650000
B39: 私域 | C39: 775000 | D39: 633423.97 | E39: 823712.13 | F39: 2232136.1
B42: 基础版 | H42: 业务非常规举措版
B43: 利润金额 | C43: 1月 | D43: 2月 | E43: 3月 | F43: Q1 | H43: 利润金额 | I43: 1月 | J43: 2月 | K43: 3月 | L43: Q1
B44: 存量整体 | C44: 20820547 | D44: 14409561 | E44: 16416014 | F44: 51646122 | H44: 存量整体 | I44: 21655547 | J44: 15169561 | K44: 17491014 | L44: 54316122
B45: 仅电视端及APP业务 （含自营业务） | C45: 17900929 | D45: 12136832 | E45: 13496396 | F45: 43534158 | H45: 仅电视端及APP业务 （含自营业务） | I45: 18435929 | J45: 12896832 | K45: 14571396 | L45: 45904158
B46: 数据库营销 | C46: 2241015.1 | D46: 1659797 | E46: 2241015.1 | F46: 6141827.1 | H46: 数据库营销 | I46: 2541015.1 | J46: 1659797 | K46: 2241015.1 | L46: 6441827.1
B47: 私域 | C47: 678602.73 | D47: 612931.5 | E47: 678602.73 | F47: 1970137 | H47: 私域 | I47: 678602.73 | J47: 612931.5 | K47: 678602.73 | L47: 1970137
B49: 基础版 | H49: 业务非常规举措版
B50: 预测达成率 | C50: 1月 | D50: 2月 | E50: 3月 | F50: Q1 | H50: 预测达成率 | I50: 1月 | J50: 2月 | K50: 3月 | L50: Q1
B51: 存量整体 | C51: 0.89640648 | D51: 0.89032304 | E51: 0.86935287 | F51: 0.88595414 | H51: 存量整体 | I51: 0.93235652 | J51: 0.93728113 | K51: 0.9262823 | L51: 0.93175618
B52: 仅电视端及APP业务 （含自营业务） | C52: 0.91323441 | D52: 0.86994779 | E52: 0.8510075 | F52: 0.8810404 | H52: 仅电视端及APP业务 （含自营业务） | I52: 0.94052799 | J52: 0.92442331 | K52: 0.918791 | L52: 0.92900425
B53: 数据库营销 | C53: 0.78632107 | D53: 1.0373731 | E53: 1.0186432 | F53: 0.92358302 | H53: 数据库营销 | I53: 0.89158423 | J53: 1.0373731 | K53: 1.0186432 | L53: 0.9686958
B54: 私域 | C54: 0.87561643 | D54: 0.96764811 | E54: 0.82383481 | F54: 0.88262403 | H54: 私域 | I54: 0.87561643 | J54: 0.96764811 | K54: 0.82383481 | L54: 0.88262403

Sheet 1. 按目标v0.2
B2: 25年实际 | X2: 25年实际利润 | AT2: 25年实际
B3: 销售金额 | C3: 1月 | D3: 2月 | E3: 3月 | F3: 4月 | G3: 5月 | H3: 6月 | I3: 7月 | J3: 8月 | K3: 9月 | L3: 10月 | M3: 11月 | N3: 12月 | O3: 合计 | P3: H1 | Q3: H2 | R3: Q1 | S3: Q2 | T3: Q3 | U3: Q4 | X3: 利润金额 | Y3: 1月 | Z3: 2月 | AA3: 3月 | AB3: 4月 | AC3: 5月 | AD3: 6月 | AE3: 7月 | AF3: 8月 | AG3: 9月 | AH3: 10月 | AI3: 11月 | AJ3: 12月 | AK3: 合计 | AL3: H1 | AM3: H2 | AN3: Q1 | AO3: Q2 | AP3: Q3 | AQ3: Q4 | AT3: 手动毛利率 | AU3: 1月 | AV3: 2月 | AW3: 3月 | AX3: 4月 | AY3: 5月 | AZ3: 6月 | BA3: 7月 | BB3: 8月 | BC3: 9月 | BD3: 10月 | BE3: 11月 | BF3: 12月e | BG3: 合计 | BH3: H1 | BI3: H2 | BJ3: Q1 | BK3: Q2 | BL3: Q3 | BM3: Q4
A4: 25年口径 | B4: 1电视及APP业务（含自营旅游） | C4: 1.0781329e+08 | D4: 81747623 | E4: 84492124 | F4: 84646543 | G4: 83475150 | H4: 78490927 | I4: 80703402 | J4: 74913585 | K4: 83150977 | L4: 90542776 | M4: 88943142 | N4: 82689520 | O4: =SUM(C4:N4) -> 1.0216091e+09 | P4: =SUM(C4:H4) -> 5.2066566e+08 | Q4: =SUM(I4:N4) -> 5.009434e+08 | R4: =SUM(C4:E4) -> 2.7405304e+08 | S4: =SUM(F4:H4) -> 246612620 | T4: =SUM(I4:K4) -> 238767964 | U4: =SUM(L4:N4) -> 2.6217544e+08 | V4: 0.91806803 | W4: 25年口径 | X4: 1电视及APP业务（含自营旅游） | Y4: 25910624 | Z4: 18677402 | AA4: 20898078 | AB4: 20177139 | AC4: 18790332 | AD4: 19119339 | AE4: 18619342 | AF4: 17665712 | AG4: 17937357 | AH4: 17492227 | AI4: 21609474 | AJ4: 22762989 | AK4: =SUM(Y4:AJ4) -> 2.3966002e+08 | AL4: =SUM(Y4:AD4) -> 1.2357291e+08 | AM4: =SUM(AE4:AJ4) -> 1.160871e+08 | AN4: =SUM(Y4:AA4) -> 65486104 | AO4: =SUM(AB4:AD4) -> 58086810 | AP4: =SUM(AE4:AG4) -> 54222411 | AQ4: =SUM(AH4:AJ4) -> 61864690 | AR4: 0.905767 | AS4: 1.12 | AT4: 1电视及APP业务（含自营旅游） | AU4: =Y4*$AS4/C4 -> 0.2691681 | AV4: =Z4*$AS4/D4 -> 0.25589356 | AW4: =AA4*$AS4/E4 -> 0.2770181 | AX4: =AB4*$AS4/F4 -> 0.26697364 | AY4: =AC4*$AS4/G4 -> 0.25211302 | AZ4: =AD4*$AS4/H4 -> 0.272817 | BA4: =AE4*$AS4/I4 -> 0.25839882 | BB4: =AF4*$AS4/J4 -> 0.26411227 | ... BM4: =AQ4*$AS4/U4 -> 0.26428278
A5: 25年口径 | B5: 7数据库营销 | C5: 11875837 | D5: 9505244.6 | E5: 8448582.2 | F5: 10411125 | G5: 7751860 | H5: 8753480.6 | I5: 9067021.2 | J5: 7495744.8 | K5: 13999988 | L5: 18029060 | M5: 16780507 | N5: 8632591.5 | O5: =SUM(C5:N5) -> 1.3075104e+08 | P5: =SUM(C5:H5) -> 56746130 | Q5: =SUM(I5:N5) -> 74004912 | R5: =SUM(C5:E5) -> 29829664 | S5: =SUM(F5:H5) -> 26916466 | T5: =SUM(I5:K5) -> 30562754 | U5: =SUM(L5:N5) -> 43442158 | V5: 0.91563774 | W5: 25年口径 | X5: 7数据库营销 | Y5: 2549751.2 | Z5: 1880081.8 | AA5: 2130051.2 | AB5: 2615080.4 | AC5: 1752152.4 | AD5: 2225886 | AE5: 1876419.1 | AF5: 1908652.7 | AG5: 2008057.6 | AH5: 1945294.6 | AI5: 3494718 | AJ5: 2180017.1 | AK5: =SUM(Y5:AJ5) -> 26566162 | AL5: =SUM(Y5:AD5) -> 13153003 | AM5: =SUM(AE5:AJ5) -> 13413159 | AN5: =SUM(Y5:AA5) -> 6559884.2 | AO5: =SUM(AB5:AD5) -> 6593118.8 | AP5: =SUM(AE5:AG5) -> 5793129.4 | AQ5: =SUM(AH5:AJ5) -> 7620029.7 | AR5: 0.90104535 | AS5: 1.12 | AT5: 7数据库营销 | AU5: =Y5*$AS5/C5 -> 0.24046484 | AV5: =Z5*$AS5/D5 -> 0.22152945 | AW5: =AA5*$AS5/E5 -> 0.28237369 | AX5: =AB5*$AS5/F5 -> 0.28132311 | AY5: =AC5*$AS5/G5 -> 0.25315353 | AZ5: =AD5*$AS5/H5 -> 0.28480012 | BA5: =AE5*$AS5/I5 -> 0.23178388 | BB5: =AF5*$AS5/J5 -> 0.28518727 | ... BM5: =AQ5*$AS5/U5 -> 0.19645509
A6: 25年口径 | B6: 8私域整体 | C6: 5280469.7 | D6: 5228202.1 | E6: 5686460.7 | F6: 4949084.3 | G6: 4623575.5 | H6: 4963729.5 | I6: 5789922.8 | J6: 7084063.3 | K6: 5517952.4 | L6: 6676835 | M6: 5965314.6 | N6: 7951606.3 | O6: =SUM(C6:N6) -> 69717216 | P6: =SUM(C6:H6) -> 30731522 | Q6: =SUM(I6:N6) -> 38985694 | R6: =SUM(C6:E6) -> 16195133 | S6: =SUM(F6:H6) -> 14536389 | T6: =SUM(I6:K6) -> 18391938 | U6: =SUM(L6:N6) -> 20593756 | V6: 0.87837455 | W6: 25年口径 | X6: 8私域整体 | Y6: 573137.28 | Z6: 613994.73 | AA6: 694290.26 | AB6: 571341.18 | AC6: 565277.8 | AD6: 628136.96 | AE6: 728343.65 | AF6: 803735.23 | AG6: 605885.04 | AH6: 791985.12 | AI6: 680080.68 | AJ6: 799188.63 | AK6: =SUM(Y6:AJ6) -> 8055396.6 | AL6: =SUM(Y6:AD6) -> 3646178.2 | AM6: =SUM(AE6:AJ6) -> 4409218.3 | AN6: =SUM(Y6:AA6) -> 1881422.3 | AO6: =SUM(AB6:AD6) -> 1764755.9 | AP6: =SUM(AE6:AG6) -> 2137963.9 | AQ6: =SUM(AH6:AJ6) -> 2271254.4 | AR6: 0.89709832 | AS6: 1.12 | AT6: 8私域整体 | AU6: =Y6*$AS6/C6 -> 0.12156376 | AV6: =Z6*$AS6/D6 -> 0.13153166 | AW6: =AA6*$AS6/E6 -> 0.13674676 | AX6: =AB6*$AS6/F6 -> 0.12929707 | AY6: =AC6*$AS6/G6 -> 0.13693107 | AZ6: =AD6*$AS6/H6 -> 0.14173081 | BA6: =AE6*$AS6/I6 -> 0.14089046 | BB6: =AF6*$AS6/J6 -> 0.12707163 | ... BM6: =AQ6*$AS6/U6 -> 0.12352312
A7: 25年口径 | B7: 9私域-东购商品 | C7: 2871360.4 | D7: 3366411.8 | E7: 3379447.8 | F7: 2675906.4 | G7: 2563448.3 | H7: 3021255.9 | I7: 3773571 | J7: 5072870 | K7: 3530388.4 | L7: 4745655.6 | M7: 3798862.2 | N7: 6133310.3 | O7: =SUM(C7:N7) -> 44932488 | P7: =SUM(C7:H7) -> 17877831 | Q7: =SUM(I7:N7) -> 27054658 | R7: =SUM(C7:E7) -> 9617219.9 | S7: =SUM(F7:H7) -> 8260610.6 | T7: =SUM(I7:K7) -> 12376829 | U7: =SUM(L7:N7) -> 14677828 | V7: 0.85024824 | W7: 25年口径 | X7: 9私域-东购商品 | Y7: 300071.9 | Z7: 384120.96 | AA7: 411329.62 | AB7: 328537.07 | AC7: 327206.24 | AD7: 401054.42 | AE7: 491893.96 | AF7: 570942.71 | AG7: 381189.1 | AH7: 568369.12 | AI7: 445359.18 | AJ7: 591029.63 | AK7: =SUM(Y7:AJ7) -> 5201103.9 | AL7: =SUM(Y7:AD7) -> 2152320.2 | AM7: =SUM(AE7:AJ7) -> 3048783.7 | AN7: =SUM(Y7:AA7) -> 1095522.5 | AO7: =SUM(AB7:AD7) -> 1056797.7 | AP7: =SUM(AE7:AG7) -> 1444025.8 | AQ7: =SUM(AH7:AJ7) -> 1604757.9 | AR7: 0.88615695 | AS7: 1.12 | AT7: 9私域-东购商品 | AU7: =Y7*$AS7/C7 -> 0.11704575 | AV7: =Z7*$AS7/D7 -> 0.12779645 | AW7: =AA7*$AS7/E7 -> 0.13632084 | AX7: =AB7*$AS7/F7 -> 0.13750911 | AY7: =AC7*$AS7/G7 -> 0.14296016 | AZ7: =AD7*$AS7/H7 -> 0.14867359 | BA7: =AE7*$AS7/I7 -> 0.14599467 | BB7: =AF7*$AS7/J7 -> 0.12605406 | ... BM7: =AQ7*$AS7/U7 -> 0.12245196
A8: 25年口径 | B8: 10私域-第三方 | C8: 2409109.3 | D8: 1861790.4 | E8: 2307012.9 | F8: 2273177.9 | G8: 2060127.2 | H8: 1942473.6 | I8: 2016351.9 | J8: 2011193.3 | K8: 1987563.9 | L8: 1931179.4 | M8: 2166452.5 | N8: 1818296 | O8: =SUM(C8:N8) -> 24784728 | P8: =SUM(C8:H8) -> 12853691 | Q8: =SUM(I8:N8) -> 11931037 | R8: =SUM(C8:E8) -> 6577912.6 | S8: =SUM(F8:H8) -> 6275778.7 | T8: =SUM(I8:K8) -> 6015109.1 | U8: =SUM(L8:N8) -> 5915927.8 | V8: 0.90245668 | W8: 25年口径 | X8: 10私域-第三方 | Y8: 273065.38 | Z8: 229873.77 | AA8: 282960.64 | AB8: 242804.11 | AC8: 238071.56 | AD8: 227082.54 | AE8: 236449.69 | AF8: 232792.52 | AG8: 224695.94 | AH8: 223616 | AI8: 234721.5 | AJ8: 208159 | AK8: =SUM(Y8:AJ8) -> 2854292.6 | AL8: =SUM(Y8:AD8) -> 1493858 | AM8: =SUM(AE8:AJ8) -> 1360434.6 | AN8: =SUM(Y8:AA8) -> 785899.79 | AO8: =SUM(AB8:AD8) -> 707958.21 | AP8: =SUM(AE8:AG8) -> 693938.15 | AQ8: =SUM(AH8:AJ8) -> 666496.5 | AR8: 0.90681515 | AS8: 1.12 | AT8: 10私域-第三方 | AU8: =Y8*$AS8/C8 -> 0.12694867 | AV8: =Z8*$AS8/D8 -> 0.1382855 | AW8: =AA8*$AS8/E8 -> 0.13737067 | AX8: =AB8*$AS8/F8 -> 0.11963015 | AY8: =AC8*$AS8/G8 -> 0.12942897 | AZ8: =AD8*$AS8/H8 -> 0.13093226 | BA8: =AE8*$AS8/I8 -> 0.13133802 | BB8: =AF8*$AS8/J8 -> 0.12963827 | ... BM8: =AQ8*$AS8/U8 -> 0.12618073
B9: 存量整体 | C9: =C4+C8 -> 1.102224e+08 | D9: =D4+D8 -> 83609413 | E9: =E4+E8 -> 86799137 | F9: =F4+F8 -> 86919721 | G9: =G4+G8 -> 85535277 | H9: =H4+H8 -> 80433401 | I9: =I4+I8 -> 82719754 | J9: =J4+J8 -> 76924778 | ... N9: =N4+N8 -> 84507816 | O9: =SUM(C9:N9) -> 1.0463938e+09 | P9: =SUM(C9:H9) -> 5.3351935e+08 | Q9: =SUM(I9:N9) -> 5.1287444e+08 | R9: =SUM(C9:E9) -> 2.8063095e+08 | S9: =SUM(F9:H9) -> 2.528884e+08 | T9: =SUM(I9:K9) -> 2.4478307e+08 | U9: =SUM(L9:N9) -> 2.6809137e+08 | X9: 存量整体 | Y9: =Y4+Y8 -> 26183689 | Z9: =Z4+Z8 -> 18907276 | AA9: =AA4+AA8 -> 21181039 | AB9: =AB4+AB8 -> 20419943 | AC9: =AC4+AC8 -> 19028404 | AD9: =AD4+AD8 -> 19346421 | AE9: =AE4+AE8 -> 18855792 | AF9: =AF4+AF8 -> 17898504 | ... AJ9: =AJ4+AJ8 -> 22971148 | AK9: =SUM(Y9:AJ9) -> 2.4251431e+08 | AL9: =SUM(Y9:AD9) -> 1.2506677e+08 | AM9: =SUM(AE9:AJ9) -> 1.1744754e+08 | AN9: =SUM(Y9:AA9) -> 66272004 | AO9: =SUM(AB9:AD9) -> 58794768 | AP9: =SUM(AE9:AG9) -> 54916349 | AQ9: =SUM(AH9:AJ9) -> 62531187 | AS9: 1.12 | AT9: 存量整体 | AU9: =Y9*$AS9/C9 -> 0.26605964 | AV9: =Z9*$AS9/D9 -> 0.2532747 | AW9: =AA9*$AS9/E9 -> 0.27330645 | AX9: =AB9*$AS9/F9 -> 0.26312022 | AY9: =AC9*$AS9/G9 -> 0.24915816 | AZ9: =AD9*$AS9/H9 -> 0.26939047 | BA9: =AE9*$AS9/I9 -> 0.25530162 | BB9: =AF9*$AS9/J9 -> 0.26059646 | ... BM9: =AQ9*$AS9/U9 -> 0.2612353
A10: 26年口径 | B10: 仅电视端及APP业务 （含自营业务） | C10: =C4-C11-C7 -> 93066095 | D10: =D4-D11-D7 -> 68875967 | E10: =E4-E11-E7 -> 72664094 | F10: =F4-F11-F7 -> 71559512 | G10: =G4-G11-G7 -> 73159842 | H10: =H4-H11-H7 -> 66716190 | I10: =I4-I11-I7 -> 67862810 | J10: =J4-J11-J7 -> 62344970 | ... N10: =N4-N11-N7 -> 67923619 | O10: =SUM(C10:N10) -> 8.4592553e+08 | P10: =SUM(C10:H10) -> 4.460417e+08 | Q10: =SUM(I10:N10) -> 3.9988383e+08 | R10: =SUM(C10:E10) -> 2.3460616e+08 | S10: =SUM(F10:H10) -> 2.1143554e+08 | T10: =SUM(I10:K10) -> 1.9582838e+08 | U10: =SUM(L10:N10) -> 2.0405545e+08 | W10: 26年口径 | X10: 仅电视端及APP业务 （含自营业务） | Y10: =Y4-Y11-Y7 -> 23060801 | Z10: =Z4-Z11-Z7 -> 16413199 | AA10: =AA4-AA11-AA7 -> 18356698 | AB10: =AB4-AB11-AB7 -> 17233521 | AC10: =AC4-AC11-AC7 -> 16710974 | AD10: =AD4-AD11-AD7 -> 16492398 | AE10: =AE4-AE11-AE7 -> 16251029 | AF10: =AF4-AF11-AF7 -> 15186116 | ... AJ10: =AJ4-AJ11-AJ7 -> 19991942 | AK10: =SUM(Y10:AJ10) -> 2.0789275e+08 | AL10: =SUM(Y10:AD10) -> 1.0826759e+08 | AM10: =SUM(AE10:AJ10) -> 99625158 | AN10: =SUM(Y10:AA10) -> 57830698 | AO10: =SUM(AB10:AD10) -> 50436894 | AP10: =SUM(AE10:AG10) -> 46985256 | AQ10: =SUM(AH10:AJ10) -> 52639903 | AS10: 1.12 | AT10: 仅电视端及APP业务 （含自营业务） | AU10: =Y10*$AS10/C10 -> 0.27752424 | AV10: =Z10*$AS10/D10 -> 0.26689692 | AW10: =AA10*$AS10/E10 -> 0.28293893 | AX10: =AB10*$AS10/F10 -> 0.26972716 | AY10: =AC10*$AS10/G10 -> 0.25582738 | AZ10: =AD10*$AS10/H10 -> 0.27686662 | BA10: =AE10*$AS10/I10 -> 0.26820512 | BB10: =AF10*$AS10/J10 -> 0.2728119 | ... BM10: =AQ10*$AS10/U10 -> 0.28892485
A11: 26年口径 | B11: 数据库营销 | C11: =C5 -> 11875837 | D11: =D5 -> 9505244.6 | E11: =E5 -> 8448582.2 | F11: =F5 -> 10411125 | G11: =G5 -> 7751860 | H11: =H5 -> 8753480.6 | I11: =I5 -> 9067021.2 | J11: =J5 -> 7495744.8 | ... N11: =N5 -> 8632591.5 | O11: =SUM(C11:N11) -> 1.3075104e+08 | P11: =SUM(C11:H11) -> 56746130 | Q11: =SUM(I11:N11) -> 74004912 | R11: =SUM(C11:E11) -> 29829664 | S11: =SUM(F11:H11) -> 26916466 | T11: =SUM(I11:K11) -> 30562754 | U11: =SUM(L11:N11) -> 43442158 | W11: 26年口径 | X11: 数据库营销 | Y11: =Y5 -> 2549751.2 | Z11: =Z5 -> 1880081.8 | AA11: =AA5 -> 2130051.2 | AB11: =AB5 -> 2615080.4 | AC11: =AC5 -> 1752152.4 | AD11: =AD5 -> 2225886 | AE11: =AE5 -> 1876419.1 | AF11: =AF5 -> 1908652.7 | ... AJ11: =AJ5 -> 2180017.1 | AK11: =SUM(Y11:AJ11) -> 26566162 | AL11: =SUM(Y11:AD11) -> 13153003 | AM11: =SUM(AE11:AJ11) -> 13413159 | AN11: =SUM(Y11:AA11) -> 6559884.2 | AO11: =SUM(AB11:AD11) -> 6593118.8 | AP11: =SUM(AE11:AG11) -> 5793129.4 | AQ11: =SUM(AH11:AJ11) -> 7620029.7 | AS11: 1.12 | AT11: 数据库营销 | AU11: =Y11*$AS11/C11 -> 0.24046484 | AV11: =Z11*$AS11/D11 -> 0.22152945 | AW11: =AA11*$AS11/E11 -> 0.28237369 | AX11: =AB11*$AS11/F11 -> 0.28132311 | AY11: =AC11*$AS11/G11 -> 0.25315353 | AZ11: =AD11*$AS11/H11 -> 0.28480012 | BA11: =AE11*$AS11/I11 -> 0.23178388 | BB11: =AF11*$AS11/J11 -> 0.28518727 | ... BM11: =AQ11*$AS11/U11 -> 0.19645509
A12: 26年口径 | B12: 私域 | C12: =C6 -> 5280469.7 | D12: =D6 -> 5228202.1 | E12: =E6 -> 5686460.7 | F12: =F6 -> 4949084.3 | G12: =G6 -> 4623575.5 | H12: =H6 -> 4963729.5 | I12: =I6 -> 5789922.8 | J12: =J6 -> 7084063.3 | ... N12: =N6 -> 7951606.3 | O12: =SUM(C12:N12) -> 69717216 | P12: =SUM(C12:H12) -> 30731522 | Q12: =SUM(I12:N12) -> 38985694 | R12: =SUM(C12:E12) -> 16195133 | S12: =SUM(F12:H12) -> 14536389 | T12: =SUM(I12:K12) -> 18391938 | U12: =SUM(L12:N12) -> 20593756 | W12: 26年口径 | X12: 私域 | Y12: =Y6 -> 573137.28 | Z12: =Z6 -> 613994.73 | AA12: =AA6 -> 694290.26 | AB12: =AB6 -> 571341.18 | AC12: =AC6 -> 565277.8 | AD12: =AD6 -> 628136.96 | AE12: =AE6 -> 728343.65 | AF12: =AF6 -> 803735.23 | ... AJ12: =AJ6 -> 799188.63 | AK12: =SUM(Y12:AJ12) -> 8055396.6 | AL12: =SUM(Y12:AD12) -> 3646178.2 | AM12: =SUM(AE12:AJ12) -> 4409218.3 | AN12: =SUM(Y12:AA12) -> 1881422.3 | AO12: =SUM(AB12:AD12) -> 1764755.9 | AP12: =SUM(AE12:AG12) -> 2137963.9 | AQ12: =SUM(AH12:AJ12) -> 2271254.4 | AS12: 1.12 | AT12: 私域 | AU12: =Y12*$AS12/C12 -> 0.12156376 | AV12: =Z12*$AS12/D12 -> 0.13153166 | AW12: =AA12*$AS12/E12 -> 0.13674676 | AX12: =AB12*$AS12/F12 -> 0.12929707 | AY12: =AC12*$AS12/G12 -> 0.13693107 | AZ12: =AD12*$AS12/H12 -> 0.14173081 | BA12: =AE12*$AS12/I12 -> 0.14089046 | BB12: =AF12*$AS12/J12 -> 0.12707163 | ... BM12: =AQ12*$AS12/U12 -> 0.12352312
B13: check | C13: =SUM(C10:C12)=C9 -> TRUE | D13: =SUM(D10:D12)=D9 -> TRUE | E13: =SUM(E10:E12)=E9 -> FALSE | F13: =SUM(F10:F12)=F9 -> TRUE | G13: =SUM(G10:G12)=G9 -> TRUE | H13: =SUM(H10:H12)=H9 -> TRUE | I13: =SUM(I10:I12)=I9 -> TRUE | J13: =SUM(J10:J12)=J9 -> TRUE | ... U13: =SUM(U10:U12)=U9 -> TRUE | X13: check | Y13: =SUM(Y10:Y12)=Y9 -> TRUE | Z13: =SUM(Z10:Z12)=Z9 -> TRUE | AA13: =SUM(AA10:AA12)=AA9 -> TRUE | AB13: =SUM(AB10:AB12)=AB9 -> TRUE | AC13: =SUM(AC10:AC12)=AC9 -> TRUE | AD13: =SUM(AD10:AD12)=AD9 -> TRUE | AE13: =SUM(AE10:AE12)=AE9 -> TRUE | AF13: =SUM(AF10:AF12)=AF9 -> TRUE | ... AQ13: =SUM(AQ10:AQ12)=AQ9 -> TRUE
X14: 电视及APP-电视商品（含自营业务） | Y14: 23141348 | Z14: 16740906 | AA14: 18651063 | AB14: 18127100 | AC14: 17050642 | AD14: 17242451 | AE14: 17060422 | AF14: 16235447 | AG14: 16150202 | AH14: 15755887 | AI14: 19418912 | AJ14: 18386453 | AK14: =SUM(Y14:AJ14) -> 2.1396083e+08 | AL14: =SUM(Y14:AD14) -> 1.1095351e+08 | AM14: =SUM(AE14:AJ14) -> 1.0300732e+08 | AN14: =SUM(Y14:AA14) -> 58533318 | AO14: =SUM(AB14:AD14) -> 52420192 | AP14: =SUM(AE14:AG14) -> 49446071 | AQ14: =SUM(AH14:AJ14) -> 53561252
X15: 电视及APP-电商商品 | Y15: 2769275.6 | Z15: 1936495.7 | AA15: 2247014.9 | AB15: 2050038.4 | AC15: 1739691.9 | AD15: 1876888.2 | AE15: 1558920 | AF15: 1430264.5 | AG15: 1787154.4 | AH15: 1736339.4 | AI15: 2199376.9 | AJ15: 4376535.8 | AK15: =SUM(Y15:AJ15) -> 25707996 | AL15: =SUM(Y15:AD15) -> 12619405 | AM15: =SUM(AE15:AJ15) -> 13088591 | AN15: =SUM(Y15:AA15) -> 6952786.2 | AO15: =SUM(AB15:AD15) -> 5666618.5 | AP15: =SUM(AE15:AG15) -> 4776338.9 | AQ15: =SUM(AH15:AJ15) -> 8312252.1
X16: 电视端及APP业务
X17: 自营旅游
W20: 趋势环比 | X20: 利润金额环比 | Y20: 1月 | Z20: 2月 | AA20: 3月 | AB20: 4月 | AC20: 5月 | AD20: 6月 | AE20: 7月 | AF20: 8月 | AG20: 9月 | AH20: 10月 | AI20: 11月 | AJ20: 12月
W21: 30641423 | X21: 存量整体 | Y21: -0.14548063 | Z21: =Z9/Y9-1 -> -0.27789871 | AA21: =AA9/Z9-1 -> 0.12025864 | AB21: =AB9/AA9-1 -> -0.035932897 | AC21: =AC9/AB9-1 -> -0.068146074 | AD21: =AD9/AC9-1 -> 0.016712761 | AE21: =AE9/AD9-1 -> -0.025360201 | AF21: =AF9/AE9-1 -> -0.05076891 | AG21: =AG9/AF9-1 -> 0.014724625 | ... AJ21: =AJ9/AI9-1 -> 0.051590449
W22: =W21-W24-W23 -> 27129328 | X22: 仅电视端及APP业务 （含自营业务） | Y22: -0.14996784 | Z22: =Z10/Y10-1 -> -0.28826413 | AA22: =AA10/Z10-1 -> 0.1184107 | AB22: =AB10/AA10-1 -> -0.061186181 | AC22: =AC10/AB10-1 -> -0.030321578 | AD22: =AD10/AC10-1 -> -0.013079764 | AE22: =AE10/AD10-1 -> -0.014635162 | AF22: =AF10/AE10-1 -> -0.065528968 | AG22: =AG10/AF10-1 -> 0.023837171 | ... AJ22: =AJ10/AI10-1 -> 0.13144448
W23: 2796841.2 | X23: 数据库营销 | Y23: -0.088346096 | Z23: =Z11/Y11-1 -> -0.26264108 | AA23: =AA11/Z11-1 -> 0.13295666 | AB23: =AB11/AA11-1 -> 0.22770777 | AC23: =AC11/AB11-1 -> -0.32998144 | AD23: =AD11/AC11-1 -> 0.27037237 | AE23: =AE11/AD11-1 -> -0.15700126 | AF23: =AF11/AE11-1 -> 0.017178252 | AG23: =AG11/AF11-1 -> 0.052081188 | ... AJ23: =AJ11/AI11-1 -> -0.37619656
W24: 715254.05 | X24: 私域 | Y24: -0.19869411 | Z24: =Z12/Y12-1 -> 0.071287371 | AA24: =AA12/Z12-1 -> 0.1307756 | AB24: =AB12/AA12-1 -> -0.17708599 | AC24: =AC12/AB12-1 -> -0.010612538 | AD24: =AD12/AC12-1 -> 0.11120048 | AE24: =AE12/AD12-1 -> 0.15953 | AF24: =AF12/AE12-1 -> 0.103511 | AG24: =AG12/AF12-1 -> -0.24616339 | ... AJ24: =AJ12/AI12-1 -> 0.17513797
B28: 销售额占比 | C28: 1月 | D28: 2月 | E28: 3月 | F28: 4月 | G28: 5月 | H28: 6月 | I28: 7月 | J28: 8月 | K28: 9月 | L28: 10月 | M28: 11月 | N28: 12月 | O28: 合计 | P28: H1 | Q28: H2 | R28: Q1 | S28: Q2 | T28: Q3 | U28: Q4 | X28: 利润额占比 | Y28: 1月 | Z28: 2月 | AA28: 3月 | AB28: 4月 | AC28: 5月 | AD28: 6月 | AE28: 7月 | AF28: 8月 | AG28: 9月 | AH28: 10月 | AI28: 11月 | AJ28: 12月 | AK28: 合计 | AL28: H1 | AM28: H2 | AN28: Q1 | AO28: Q2 | AP28: Q3 | AQ28: Q4
B29: 存量整体 | C29: =C9/$O9 -> 0.10533549 | D29: =D9/$O9 -> 0.079902436 | E29: =E9/$O9 -> 0.082950738 | F29: =F9/$O9 -> 0.083065975 | G29: =G9/$O9 -> 0.081742914 | H29: =H9/$O9 -> 0.076867238 | I29: =I9/$O9 -> 0.079052222 | J29: =J9/$O9 -> 0.073514177 | ... U29: =U9/$O9 -> 0.25620504 | X29: 存量整体 | Y29: =Y9/$AK9 -> 0.10796761 | Z29: =Z9/$AK9 -> 0.077963547 | AA29: =AA9/$AK9 -> 0.087339338 | AB29: =AB9/$AK9 -> 0.084200982 | AC29: =AC9/$AK9 -> 0.078463016 | AD29: =AD9/$AK9 -> 0.07977435 | AE29: =AE9/$AK9 -> 0.077751256 | AF29: =AF9/$AK9 -> 0.07380391 | ... AQ29: =AQ9/$AK9 -> 0.25784535
B30: 仅电视端及APP业务 （含自营业务） | C30: =C10/$O10 -> 0.11001689 | D30: =D10/$O10 -> 0.081420839 | E30: =E10/$O10 -> 0.085898925 | F30: =F10/$O10 -> 0.084593157 | G30: =G10/$O10 -> 0.086484967 | H30: =H10/$O10 -> 0.078867687 | I30: =I10/$O10 -> 0.080223149 | J30: =J10/$O10 -> 0.073700306 | ... U30: =U10/$O10 -> 0.24122153 | X30: 仅电视端及APP业务 （含自营业务） | Y30: =Y10/$AK10 -> 0.11092643 | Z30: =Z10/$AK10 -> 0.078950321 | AA30: =AA10/$AK10 -> 0.088298883 | AB30: =AB10/$AK10 -> 0.082896212 | AC30: =AC10/$AK10 -> 0.080382668 | AD30: =AD10/$AK10 -> 0.079331282 | AE30: =AE10/$AK10 -> 0.078170255 | AF30: =AF10/$AK10 -> 0.073047839 | ... AQ30: =AQ10/$AK10 -> 0.25320702
B31: 数据库营销 | C31: =C11/$O11 -> 0.090827861 | D31: =D11/$O11 -> 0.072697276 | E31: =E11/$O11 -> 0.064615793 | F31: =F11/$O11 -> 0.079625561 | G31: =G11/$O11 -> 0.059287176 | H31: =H11/$O11 -> 0.066947693 | I31: =I11/$O11 -> 0.06934569 | J31: =J11/$O11 -> 0.057328375 | ... U31: =U11/$O11 -> 0.33225095 | X31: 数据库营销 | Y31: =Y11/$AK11 -> 0.095977401 | Z31: =Z11/$AK11 -> 0.070769793 | AA31: =AA11/$AK11 -> 0.080179109 | AB31: =AB11/$AK11 -> 0.098436514 | AC31: =AC11/$AK11 -> 0.065954292 | AD31: =AD11/$AK11 -> 0.08378651 | AE31: =AE11/$AK11 -> 0.070631922 | AF31: =AF11/$AK11 -> 0.071845255 | ... AQ31: =AQ11/$AK11 -> 0.28683216
B32: 私域 | C32: =C12/$O12 -> 0.075741258 | D32: =D12/$O12 -> 0.07499155 | E32: =E12/$O12 -> 0.081564656 | F32: =F12/$O12 -> 0.070987979 | G32: =G12/$O12 -> 0.066318992 | H32: =H12/$O12 -> 0.071198045 | I32: =I12/$O12 -> 0.083048681 | J32: =J12/$O12 -> 0.10161139 | ... U32: =U12/$O12 -> 0.29538982 | X32: 私域 | Y32: =Y12/$AK12 -> 0.07114948 | Z32: =Z12/$AK12 -> 0.07622154 | AA32: =AA12/$AK12 -> 0.086189458 | AB32: =AB12/$AK12 -> 0.070926512 | AC32: =AC12/$AK12 -> 0.070173802 | AD32: =AD12/$AK12 -> 0.077977162 | AE32: =AE12/$AK12 -> 0.090416858 | AF32: =AF12/$AK12 -> 0.099775998 | ... AQ32: =AQ12/$AK12 -> 0.28195439
X33: 电视及APP-电视商品（含自营业务） | Y33: =Y14/$AK$14 -> 0.10815694 | Z33: =Z14/$AK$14 -> 0.078242855 | AA33: =AA14/$AK$14 -> 0.087170456 | AB33: =AB14/$AK$14 -> 0.08472158 | AC33: =AC14/$AK$14 -> 0.07969048 | AD33: =AD14/$AK$14 -> 0.08058695 | AE33: =AE14/$AK$14 -> 0.079736191 | AF33: =AF14/$AK$14 -> 0.075880463 | ... AQ33: =AQ14/$AK$14 -> 0.25033204
X34: 电视及APP-电商商品 | Y34: =Y15/$AK$15 -> 0.1077204 | Z34: =Z15/$AK$15 -> 0.075326592 | AA34: =AA15/$AK$15 -> 0.087405293 | AB34: =AB15/$AK$15 -> 0.079743222 | AC34: =AC15/$AK$15 -> 0.067671238 | AD34: =AD15/$AK$15 -> 0.073007955 | AE34: =AE15/$AK$15 -> 0.0606395 | AF34: =AF15/$AK$15 -> 0.055635006 | ... AQ34: =AQ15/$AK$15 -> 0.32333334
B38: 天数 | C38: 31 | D38: 28 | E38: 31 | F38: 30 | G38: 31 | H38: 30 | I38: 31 | J38: 31 | K38: 30 | L38: 31 | M38: 30 | N38: 31 | O38: =SUM(C38:N38) -> 365 | P38: =SUM(C38:H38) -> 181 | Q38: =SUM(I38:N38) -> 184 | R38: =SUM(C38:E38) -> 90 | S38: =SUM(F38:H38) -> 91 | T38: =SUM(I38:K38) -> 92 | U38: =SUM(L38:N38) -> 92 | X38: 天数 | Y38: 31 | Z38: 28 | AA38: 31 | AB38: 30 | AC38: 31 | AD38: 30 | AE38: 31 | AF38: 31 | AG38: 30 | AH38: 31 | AI38: 30 | AJ38: 31 | AK38: =SUM(Y38:AJ38) -> 365 | AL38: =SUM(Y38:AD38) -> 181 | AM38: =SUM(AE38:AJ38) -> 184 | AN38: =SUM(Y38:AA38) -> 90 | AO38: =SUM(AB38:AD38) -> 91 | AP38: =SUM(AE38:AG38) -> 92 | AQ38: =SUM(AH38:AJ38) -> 92
B39: 日均销售额 | C39: 1月 | D39: 2月 | E39: 3月 | F39: 4月 | G39: 5月 | H39: 6月 | I39: 7月 | J39: 8月 | K39: 9月 | L39: 10月 | M39: 11月 | N39: 12月 | O39: 合计 | P39: H1 | Q39: H2 | R39: Q1 | S39: Q2 | T39: Q3 | U39: Q4 | X39: 日均利润额 | Y39: 1月 | Z39: 2月 | AA39: 3月 | AB39: 4月 | AC39: 5月 | AD39: 6月 | AE39: 7月 | AF39: 8月 | AG39: 9月 | AH39: 10月 | AI39: 11月 | AJ39: 12月 | AK39: 合计 | AL39: H1 | AM39: H2 | AN39: Q1 | AO39: Q2 | AP39: Q3 | AQ39: Q4
B40: 存量整体 | C40: =C9/C$38 -> 3555561.4 | D40: =D9/D$38 -> 2986050.5 | E40: =E9/E$38 -> 2799972.2 | F40: =F9/F$38 -> 2897324 | G40: =G9/G$38 -> 2759202.5 | H40: =H9/H$38 -> 2681113.4 | I40: =I9/I$38 -> 2668379.2 | J40: =J9/J$38 -> 2481444.5 | ... U40: =U9/U$38 -> 2914036.6 | W40: =30641422.9222642/31 -> 988433 | X40: 存量整体 | Y40: =Y9/Y$38 -> 844635.14 | Z40: =Z9/Z$38 -> 675259.85 | AA40: =AA9/AA$38 -> 683259.33 | AB40: =AB9/AB$38 -> 680664.77 | AC40: =AC9/AC$38 -> 613819.49 | AD40: =AD9/AD$38 -> 644880.71 | AE40: =AE9/AE$38 -> 608251.36 | AF40: =AF9/AF$38 -> 577371.1 | ... AQ40: =AQ9/AQ$38 -> 679686.81
B41: 仅电视端及APP业务 （含自营业务） | C41: =C10/C$38 -> 3002132.1 | D41: =D10/D$38 -> 2459856 | E41: =E10/E$38 -> 2344003 | F41: =F10/F$38 -> 2385317.1 | G41: =G10/G$38 -> 2359994.9 | H41: =H10/H$38 -> 2223873 | I41: =I10/I$38 -> 2189122.9 | J41: =J10/J$38 -> 2011128.1 | ... U41: =U10/U$38 -> 2217994 | W41: =W22/31 -> 875139.6 | X41: 仅电视端及APP业务 （含自营业务） | Y41: =Y10/Y$38 -> 743896.8 | Z41: =Z10/Z$38 -> 586185.69 | AA41: =AA10/AA$38 -> 592151.54 | AB41: =AB10/AB$38 -> 574450.71 | AC41: =AC10/AC$38 -> 539063.67 | AD41: =AD10/AD$38 -> 549746.61 | AE41: =AE10/AE$38 -> 524226.75 | AF41: =AF10/AF$38 -> 489874.71 | ... AQ41: =AQ10/AQ$38 -> 572172.85
B42: 数据库营销 | C42: =C11/C$38 -> 383091.53 | D42: =D11/D$38 -> 339473.02 | E42: =E11/E$38 -> 272534.91 | F42: =F11/F$38 -> 347037.5 | G42: =G11/G$38 -> 250060 | H42: =H11/H$38 -> 291782.69 | I42: =I11/I$38 -> 292484.55 | J42: =J11/J$38 -> 241798.22 | ... U42: =U11/U$38 -> 472197.37 | W42: =2796841.2/31 -> 90220.684 | X42: 数据库营销 | Y42: =Y11/Y$38 -> 82250.039 | Z42: =Z11/Z$38 -> 67145.779 | AA42: =AA11/AA$38 -> 68711.329 | AB42: =AB11/AB$38 -> 87169.347 | AC42: =AC11/AC$38 -> 56521.045 | AD42: =AD11/AD$38 -> 74196.2 | AE42: =AE11/AE$38 -> 60529.648 | AF42: =AF11/AF$38 -> 61569.442 | ... AQ42: =AQ11/AQ$38 -> 82826.41
B43: 私域 | C43: =C12/C$38 -> 170337.73 | D43: =D12/D$38 -> 186721.51 | E43: =E12/E$38 -> 183434.22 | F43: =F12/F$38 -> 164969.48 | G43: =G12/G$38 -> 149147.6 | H43: =H12/H$38 -> 165457.65 | I43: =I12/I$38 -> 186771.7 | J43: =J12/J$38 -> 228518.17 | ... U43: =U12/U$38 -> 223845.17 | W43: =715254.05/31 -> 23072.711 | X43: 私域 | Y43: =Y12/Y$38 -> 18488.299 | Z43: =Z12/Z$38 -> 21928.383 | AA43: =AA12/AA$38 -> 22396.46 | AB43: =AB12/AB$38 -> 19044.706 | AC43: =AC12/AC$38 -> 18234.768 | AD43: =AD12/AD$38 -> 20937.899 | AE43: =AE12/AE$38 -> 23494.956 | AF43: =AF12/AF$38 -> 25926.943 | ... AQ43: =AQ12/AQ$38 -> 24687.548
X44: 电视及APP-电视商品（含自营业务） | Y44: =Y14/Y$38 -> 746495.11 | Z44: =Z14/Z$38 -> 597889.52 | AA44: =AA14/AA$38 -> 601647.21 | AB44: =AB14/AB$38 -> 604236.66 | AC44: =AC14/AC$38 -> 550020.7 | AD44: =AD14/AD$38 -> 574748.37 | AE44: =AE14/AE$38 -> 550336.19 | AF44: =AF14/AF$38 -> 523724.1 | ... AQ44: =AQ14/AQ$38 -> 582187.52
X45: 电视及APP-电商商品 | Y45: =Y15/Y$38 -> 89331.471 | Z45: =Z15/Z$38 -> 69160.561 | AA45: =AA15/AA$38 -> 72484.352 | AB45: =AB15/AB$38 -> 68334.613 | AC45: =AC15/AC$38 -> 56119.094 | AD45: =AD15/AD$38 -> 62562.94 | AE45: =AE15/AE$38 -> 50287.742 | AF45: =AF15/AF$38 -> 46137.565 | ... AQ45: =AQ15/AQ$38 -> 90350.566
W49: 趋势环比 | X49: 日均利润环比 | Y49: 1月 | Z49: 2月 | AA49: 3月 | AB49: 4月 | AC49: 5月 | AD49: 6月 | AE49: 7月 | AF49: 8月 | AG49: 9月 | AH49: 10月 | AI49: 11月 | AJ49: 12月
X50: 存量整体 | Y50: -0.14548063 | Z50: =Z40/Y40-1 -> -0.20053072 | AA50: =AA40/Z40-1 -> 0.011846516 | AB50: =AB40/AA40-1 -> -0.0037973269 | AC50: =AC40/AB40-1 -> -0.098205878 | AD50: =AD40/AC40-1 -> 0.050603186 | AE50: =AE40/AD40-1 -> -0.056800195 | AF50: =AF40/AE40-1 -> -0.05076891 | AG50: =AG40/AF40-1 -> 0.048548779 | ... AJ50: =AJ40/AI40-1 -> 0.017668176
X51: 仅电视端及APP业务 （含自营业务） | Y51: -0.14996784 | Z51: =Z41/Y41-1 -> -0.21200671 | AA51: =AA41/Z41-1 -> 0.010177405 | AB51: =AB41/AA41-1 -> -0.029892387 | AC51: =AC41/AB41-1 -> -0.061601527 | AD51: =AD41/AC41-1 -> 0.019817577 | AE51: =AE41/AD41-1 -> -0.046421125 | AF51: =AF41/AE41-1 -> -0.065528968 | AG51: =AG41/AF41-1 -> 0.057965077 | ... AJ51: =AJ41/AI41-1 -> 0.094946276
X52: 数据库营销 | Y52: -0.088346096 | Z52: =Z42/Y42-1 -> -0.18363833 | AA52: =AA42/Z42-1 -> 0.023315695 | AB52: =AB42/AA42-1 -> 0.26863136 | AC52: =AC42/AB42-1 -> -0.35159494 | AD52: =AD42/AC42-1 -> 0.31271812 | AE52: =AE42/AD42-1 -> -0.18419476 | AF52: =AF42/AE42-1 -> 0.017178252 | AG52: =AG42/AF42-1 -> 0.087150561 | ... AJ52: =AJ42/AI42-1 -> -0.39631925
...

Sheet 2. 按趋势预测Q1
C2: 预测26年 | D2: 基础版 | L2: 预测26年 | M2: 业务非常规举措版 | S2: 业务增额部分
B3: 12月 | C3: 利润金额 | D3: 1月 | E3: 2月 | F3: 3月 | G3: Q1 | H3: 全年 | L3: 利润金额 | M3: 1月 | N3: 2月 | O3: 3月 | P3: Q1 | S3: 利润金额 | T3: 1月 | U3: 2月 | V3: 3月 | W3: Q1
B4: 22971148 | C4: 存量整体 | D4: =SUM(D5:D7) -> 21932055 | E4: =SUM(E5:E7) -> 15165372 | F4: =SUM(F5:F7) -> 17259164 | G4: =SUM(G5:G7) -> 54356591 | H4: 2.1760703e+08 | L4: 存量整体 | M4: =SUM(M5:M7) -> 22767055 | N4: =SUM(N5:N7) -> 15925372 | O4: =SUM(O5:O7) -> 18334164 | P4: =SUM(P5:P7) -> 57026591 | S4: 存量整体 | T4: =SUM(T5:T7) -> 835000 | U4: =SUM(U5:U7) -> 760000 | V4: =SUM(V5:V7) -> 1075000 | W4: =SUM(W5:W7) -> 2670000
B5: 19991942 | C5: 仅电视端及APP业务 （含自营业务） | D5: =B5/31*(1+D8)*31 -> 18991594 | E5: =D5/31*(1+E8)*28 -> 12876303 | F5: =E5/28*(1+F8)*31 -> 14318702 | G5: =SUM(D5:F5) -> 46186600 | H5: 1.7810703e+08 | I5: 26年涨幅 | J5: 25年最高月日均利润 | L5: 仅电视端及APP业务 （含自营业务） | M5: =D5+T5 -> 19526594 | N5: =E5+U5 -> 13636303 | O5: =F5+V5 -> 15393702 | P5: =SUM(M5:O5) -> 48556600 | S5: 仅电视端及APP业务 （含自营业务） | T5: 535000 | U5: 760000 | V5: 1075000 | W5: =SUM(T5:V5) -> 2370000
B6: 2180017.1 | C6: 数据库营销 | D6: ='1. 按目标v0.2'!$AK$42*(1+0)*D15 -> 2256304.2 | E6: ='1. 按目标v0.2'!$AK$42*(1+0)*E15*(1-0.18) -> 1671120.8 | F6: ='1. 按目标v0.2'!$AK$42*(1+0)*F15 -> 2256304.2 | G6: =SUM(D6:F6) -> 6183729.1 | H6: 27500000 | I6: 0.042213631 | J6: 116490.6 | K6: 82250.039 | L6: 数据库营销 | M6: =D6+T6 -> 2556304.2 | N6: =E6+U6 -> 1671120.8 | O6: =F6+V6 -> 2256304.2 | P6: =SUM(M6:O6) -> 6483729.1 | S6: 数据库营销 | T6: 300000 | W6: =SUM(T6:V6) -> 300000
B7: 799188.63 | C7: 私域 | D7: ='1. 按目标v0.2'!$AK$43*(1+0)*'2. 按趋势预测Q1'!D15 -> 684156.97 | E7: ='1. 按目标v0.2'!$AK$43*(1+0)*'2. 按趋势预测Q1'!E15 -> 617948.23 | F7: ='1. 按目标v0.2'!$AK$43*(1+0)*'2. 按趋势预测Q1'!F15 -> 684156.97 | G7: =SUM(D7:F7) -> 1986262.2 | H7: 12000000 | I7: 0.50187736 | J7: 25926.943 | L7: 私域 | M7: =D7+T7 -> 684156.97 | N7: =E7+U7 -> 617948.23 | O7: =F7+V7 -> 684156.97 | P7: =SUM(M7:O7) -> 1986262.2 | S7: 私域 | W7: =SUM(T7:V7) -> 0
C8: 参考24年日均环比 | D8: -0.050037558 | E8: -0.249357 | F8: 0.0044048615
D10: =D5/D$4 -> 0.86592861 | E10: =E5/E$4 -> 0.84905949 | F10: =F5/F$4 -> 0.82962899 | G10: =G5/G$4 -> 0.8496964 | H10: =H5/H$4 -> 0.81848013 | M10: =M5/M$4 -> 0.85766885 | N10: =N5/N$4 -> 0.85626276 | O10: =O5/O$4 -> 0.83961847 | P10: =P5/P$4 -> 0.85147295
D11: =D6/D$4 -> 0.10287701 | E11: =E6/E$4 -> 0.11019319 | F11: =F6/F$4 -> 0.13073079 | G11: =G6/G$4 -> 0.11376227 | H11: =H6/H$4 -> 0.12637459 | M11: =M6/M$4 -> 0.11228084 | N11: =N6/N$4 -> 0.10493449 | O11: =O6/O$4 -> 0.12306556 | P11: =P6/P$4 -> 0.11369659
D12: =D7/D$4 -> 0.031194385 | E12: =E7/E$4 -> 0.040747317 | F12: =F7/F$4 -> 0.039640216 | G12: =G7/G$4 -> 0.036541331 | H12: =H7/H$4 -> 0.055145277 | M12: =M7/M$4 -> 0.030050306 | N12: =N7/N$4 -> 0.038802749 | O12: =O7/O$4 -> 0.037315963 | P12: =P7/P$4 -> 0.034830456
C15: 天数 | D15: 31 | E15: 28 | F15: 31 | G15: 90 | L15: 天数 | M15: 31 | N15: 28 | O15: 31 | P15: 90
B16: 12月 | C16: 日均利润额 | D16: 1月 | E16: 2月 | F16: 3月 | G16: Q1 | L16: 日均利润额 | M16: 1月 | N16: 2月 | O16: 3月 | P16: Q1
B17: =B4/31 -> 741004.77 | C17: 存量整体 | D17: =D4/D$15 -> 707485.65 | E17: =E4/E$15 -> 541620.44 | F17: =F4/F$15 -> 556747.21 | G17: =G4/G$15 -> 603962.12 | L17: 存量整体 | M17: =M4/M$15 -> 734421.14 | N17: =N4/N$15 -> 568763.29 | O17: =O4/O$15 -> 591424.63 | P17: =P4/P$15 -> 633628.79
B18: =B5/31 -> 644901.36 | C18: 仅电视端及APP业务 （含自营业务） | D18: =D5/D$15 -> 612632.07 | E18: =E5/E$15 -> 459867.97 | F18: =F5/F$15 -> 461893.63 | G18: =G5/G$15 -> 513184.44 | L18: 仅电视端及APP业务 （含自营业务） | M18: =M5/M$15 -> 629890.13 | N18: =N5/N$15 -> 487010.83 | O18: =O5/O$15 -> 496571.05 | P18: =P5/P$15 -> 539517.78
B19: =B6/31 -> 70323.132 | C19: 数据库营销 | D19: =D6/D$15 -> 72784.006 | E19: =E6/E$15 -> 59682.885 | F19: =F6/F$15 -> 72784.006 | G19: =G6/G$15 -> 68708.101 | L19: 数据库营销 | M19: =M6/M$15 -> 82461.425 | N19: =N6/N$15 -> 59682.885 | O19: =O6/O$15 -> 72784.006 | P19: =P6/P$15 -> 72041.435
B20: =B7/31 -> 25780.278 | C20: 私域 | D20: =D7/D$15 -> 22069.58 | E20: =E7/E$15 -> 22069.58 | F20: =F7/F$15 -> 22069.58 | G20: =G7/G$15 -> 22069.58 | L20: 私域 | M20: =M7/M$15 -> 22069.58 | N20: =N7/N$15 -> 22069.58 | O20: =O7/O$15 -> 22069.58 | P20: =P7/P$15 -> 22069.58
C24: 日均环比 | D24: 1月 | E24: 2月 | F24: 3月 | L24: 日均环比 | M24: 1月 | N24: 2月 | O24: 3月
C25: 存量整体 | D25: =D17/B17-1 -> -0.045234681 | E25: =E17/D17-1 -> -0.23444322 | F25: =F17/E17-1 -> 0.027928739 | L25: 存量整体 | M25: =M17/B17-1 -> -0.0088847348 | N25: =N17/M17-1 -> -0.22556247 | O25: =O17/N17-1 -> 0.039843179
C26: 仅电视端及APP业务 （含自营业务） | D26: =D18/B18-1 -> -0.050037558 | E26: =E18/D18-1 -> -0.249357 | F26: =F18/E18-1 -> 0.0044048615 | L26: 仅电视端及APP业务 （含自营业务） | M26: =M18/B18-1 -> -0.023276777 | N26: =N18/M18-1 -> -0.2268321 | O26: =O18/N18-1 -> 0.019630399
C27: 数据库营销 | D27: =D19/B19-1 -> 0.034993798 | E27: =E19/D19-1 -> -0.18 | F27: =F19/E19-1 -> 0.2195122 | L27: 数据库营销 | M27: =M19/B19-1 -> 0.1726074 | N27: =N19/M19-1 -> -0.27623268 | O27: =O19/N19-1 -> 0.2195122
C28: 私域 | D28: =D20/B20-1 -> -0.14393556 | E28: =E20/D20-1 -> 0 | F28: =F20/E20-1 -> 0 | L28: 私域 | M28: =M20/B20-1 -> -0.14393556 | N28: =N20/M20-1 -> 0 | O28: =O20/N20-1 -> 0
C32: 日均占比 | D32: 1月 | E32: 2月 | F32: 3月 | G32: Q1 | L32: 日均占比 | M32: 1月 | N32: 2月 | O32: 3月 | P32: Q1
C33: 存量整体 | D33: =D4/$H4 -> 0.10078744 | E33: =E4/$H4 -> 0.069691555 | F33: =F4/$H4 -> 0.079313447 | G33: =G4/$H4 -> 0.24979244 | L33: 存量整体 | M33: =M4/$H4 -> 0.10462463 | N33: =N4/$H4 -> 0.073184089 | O33: =O4/$H4 -> 0.084253544 | P33: =P4/$H4 -> 0.26206226
C34: 仅电视端及APP业务 （含自营业务） | D34: =D5/$H5 -> 0.10663023 | E34: =E5/$H5 -> 0.072295311 | F34: =F5/$H5 -> 0.080393808 | G34: =G5/$H5 -> 0.25931935 | L34: 仅电视端及APP业务 （含自营业务） | M34: =M5/$H5 -> 0.10963404 | N34: =N5/$H5 -> 0.076562409 | O34: =O5/$H5 -> 0.086429505 | P34: =P5/$H5 -> 0.27262596
C35: 数据库营销 | D35: =D6/$H6 -> 0.082047425 | E35: =E6/$H6 -> 0.060768028 | F35: =F6/$H6 -> 0.082047425 | G35: =G6/$H6 -> 0.22486288 | L35: 数据库营销 | M35: =M6/$H6 -> 0.092956516 | N35: =N6/$H6 -> 0.060768028 | O35: =O6/$H6 -> 0.082047425 | P35: =P6/$H6 -> 0.23577197
C36: 私域 | D36: =D7/$H7 -> 0.057013081 | E36: =E7/$H7 -> 0.051495686 | F36: =F7/$H7 -> 0.057013081 | G36: =G7/$H7 -> 0.16552185 | L36: 私域 | M36: =M7/$H7 -> 0.057013081 | N36: =N7/$H7 -> 0.051495686 | O36: =O7/$H7 -> 0.057013081 | P36: =P7/$H7 -> 0.16552185
C40: 利润目标 | D40: 1月 | E40: 2月 | F40: 3月 | G40: Q1
C41: 存量整体 | D41: 23226681 | E41: 16184643 | F41: 18883028 | G41: 58294352
C42: 仅电视端及APP业务 （含自营业务） | D42: 19601681 | E42: 13951219 | F42: 15859315 | G42: 49412216
C43: 数据库营销 | D43: 2850000 | E43: 1600000 | F43: 2200000 | G43: 6650000
C44: 私域 | D44: 775000 | E44: 633423.97 | F44: 823712.13 | G44: 2232136.1
C48: 预测达成率 | D48: 1月 | E48: 2月 | F48: 3月 | G48: Q1 | L48: 预测达成率 | M48: 1月 | N48: 2月 | O48: 3月 | P48: Q1
C49: 存量整体 | D49: =D4/D41 -> 0.94426128 | E49: =E4/E41 -> 0.93702233 | F49: =F4/F41 -> 0.91400405 | G49: =G4/G41 -> 0.93245039 | L49: 存量整体 | M49: =M4/D41 -> 0.98021132 | N49: =N4/E41 -> 0.98398043 | O49: =O4/F41 -> 0.97093348 | P49: =P4/G41 -> 0.97825243
C50: 仅电视端及APP业务 （含自营业务） | D50: =D5/D42 -> 0.9688758 | E50: =E5/E42 -> 0.92295182 | F50: =F5/F42 -> 0.90285754 | G50: =G5/G42 -> 0.93472028 | L50: 仅电视端及APP业务 （含自营业务） | M50: =M5/D42 -> 0.99616938 | N50: =N5/E42 -> 0.97742734 | O50: =O5/F42 -> 0.97064104 | P50: =P5/G42 -> 0.98268413
C51: 数据库营销 | D51: =D6/D43 -> 0.79168568 | E51: =E6/E43 -> 1.0444505 | F51: =F6/F43 -> 1.0255928 | G51: =G6/G43 -> 0.92988408 | L51: 数据库营销 | M51: =M6/D43 -> 0.89694883 | N51: =N6/E43 -> 1.0444505 | O51: =O6/F43 -> 1.0255928 | P51: =P6/G43 -> 0.97499686
C52: 私域 | D52: =D7/D44 -> 0.88278318 | E52: =E7/E44 -> 0.97556812 | F52: =F7/F44 -> 0.83057775 | G52: =G7/G44 -> 0.88984814 | L52: 私域 | M52: =M7/D44 -> 0.88278318 | N52: =N7/E44 -> 0.97556812 | O52: =O7/F44 -> 0.83057775 | P52: =P7/G44 -> 0.88984814
C56: 25年利润实际 | D56: 1月 | E56: 2月 | F56: 3月 | G56: Q1
C57: 存量整体 | D57: 26183689 | E57: 18907276 | F57: 21181039 | G57: 66272004
C58: 仅电视端及APP业务 （含自营业务） | D58: 23060801 | E58: 16413199 | F58: 18356698 | G58: 57830698
C59: 数据库营销 | D59: 2549751.2 | E59: 1880081.8 | F59: 2130051.2 | G59: 6559884.2
...

Sheet 3. 移动端分月目标
A1: GMV
A2: 统计月份 | B2: GMV目标-总 | C2: GMV目标-自有供应链 | G2: 周 | H2: 日
A3: 46023 | B3: 35750000 | C3: 3200000 | D3: =C3*0.8/1.13 -> 2265486.7 | E3: =D3+D20 -> 5299226.5 | G3: =C3/31*7 -> 722580.65 | H3: =B3/31 -> 1153225.8
A4: 46054 | B4: 22750000 | C4: 2600000 | H4: =B4/28 -> 812500 | J4: 47854856 | K4: =B3+B4-J4 -> 10645144
A5: 46082 | B5: 32500000 | C5: 5800000 | E5: =B5/310000 -> 104.83871
A6: 46113 | B6: 52000000 | C6: 13500000 | D6: =B6/B5-1 -> 0.6 | E6: =B6/300000 -> 173.33333 | F6: =E6/E5-1 -> 0.65333333 | G6: 36683171 | H6: =B6/G6-1 -> 0.41754377
A7: 46143 | B7: 55250000 | C7: 12750000
A8: 46174 | B8: 61750000 | C8: 14250000
A9: 46204 | B9: 58500000 | C9: 15000000
A10: 46235 | B10: 61750000 | C10: 15000000
A11: 46266 | B11: 61750000 | C11: 15000000
A12: 46296 | B12: 55250000 | C12: 16750000
A13: 46327 | B13: 84500000 | C13: 21250000
A14: 46357 | B14: 68250000 | C14: 14900000
A15: 2026年 | B15: =SUM(B3:B14) -> 650000000 | C15: =SUM(C3:C14) -> 150000000
A18: 利润
A19: 统计月份 | B19: 利润目标-总 | C19: 利润目标-自有供应链
A20: 46023 | B20: 3721244.2 | C20: 687504.43 | D20: =B20-C20 -> 3033739.7
A21: 46054 | B21: 2604870.9 | C21: 558597.35
A22: 46082 | B22: 3721244.2 | C22: 1246101.8
A23: 46113 | B23: 5581866.2 | C23: 2900409.3
A24: 46143 | B24: 5953990.6 | C24: 2739275.5
A25: 46174 | B25: 6698239.5 | C25: 3061543.1
A26: 46204 | B26: 6698239.5 | C26: 3222677
A27: 46235 | B27: 7070363.9 | C27: 3222677
A28: 46266 | B28: 7070363.9 | C28: 3222677
A29: 46296 | B29: 6698239.5 | C29: 3598656
A30: 46327 | B30: 10047359 | C30: 4565459.1
A31: 46357 | B31: 8558861.6 | C31: 3201192.5
A32: 2026年 | B32: =SUM(B20:B31) -> 74424883 | C32: =SUM(C20:C31) -> 32226770
A35: 销售
A36: 统计月份 | B36: 利润目标-总 | C36: 利润目标-自有供应链
A37: 46023 | B37: 21092500 | C37: 2048000
A38: 46054 | B38: 13422500 | C38: 1664000
A39: 46082 | B39: 19175000 | C39: 3712000
A40: 46113 | B40: 30680000 | C40: 8640000
A41: 46143 | B41: 32597500 | C41: 8160000
A42: 46174 | B42: 36432500 | C42: 9120000
A43: 46204 | B43: 34515000 | C43: 9600000
A44: 46235 | B44: 36432500 | C44: 9600000
...

Sheet 4. 实际达成与同比
B3: 25年实际销售 | X3: 25年实际利润
B4: 销售金额 | C4: 1月 | D4: 2月 | E4: 3月 | F4: 4月 | G4: 5月 | H4: 6月 | I4: 7月 | J4: 8月 | K4: 9月 | L4: 10月 | M4: 11月 | N4: 12月 | O4: 合计 | P4: H1 | Q4: H2 | R4: Q1 | S4: Q2 | T4: Q3 | U4: Q4 | X4: 利润金额 | Y4: 1月 | Z4: 2月 | AA4: 3月 | AB4: 4月 | AC4: 5月 | AD4: 6月 | AE4: 7月 | AF4: 8月 | AG4: 9月 | AH4: 10月 | AI4: 11月 | AJ4: 12月 | AK4: 合计 | AL4: H1 | AM4: H2 | AN4: Q1 | AO4: Q2 | AP4: Q3 | AQ4: Q4
B5: 存量整体 | C5: 1.102224e+08 | D5: 83609413 | E5: 86799137 | F5: 86919721 | G5: 85535277 | H5: 80433401 | I5: 82719754 | J5: 76924778 | K5: 85138541 | L5: 92473955 | M5: 91194584 | N5: 84507816 | O5: 1.0464788e+09 | P5: 5.3351935e+08 | Q5: 5.1295943e+08 | R5: 2.8063095e+08 | S5: 2.528884e+08 | T5: 2.4478307e+08 | U5: 2.6817636e+08 | X5: 存量整体 | Y5: 26183689 | Z5: 18907276 | AA5: 21181039 | AB5: 20419943 | AC5: 19028404 | AD5: 19346421 | AE5: 18855792 | AF5: 17898504 | AG5: 18162053 | AH5: 17715843 | AI5: 21853011 | AJ5: 22971148 | AK5: 2.4252312e+08 | AL5: 1.2506677e+08 | AM5: 1.1745635e+08 | AN5: 66272004 | AO5: 58794768 | AP5: 54916349 | AQ5: 62540002
A6: 26年口径 | B6: 仅电视端及APP业务 （含自营业务） | C6: 93066095 | D6: 68875967 | E6: 72664094 | F6: 71559512 | G6: 73159842 | H6: 66716190 | I6: 67862810 | J6: 62344970 | K6: 65620601 | L6: 67768060 | M6: 68448763 | N6: 67923619 | O6: 8.4601052e+08 | P6: 4.460417e+08 | Q6: 3.9996882e+08 | R6: 2.3460616e+08 | S6: 2.1143554e+08 | T6: 1.9582838e+08 | U6: 2.0414044e+08 | W6: 26年口径 | X6: 仅电视端及APP业务 （含自营业务） | Y6: 23060801 | Z6: 16413199 | AA6: 18356698 | AB6: 17233521 | AC6: 16710974 | AD6: 16492398 | AE6: 16251029 | AF6: 15186116 | AG6: 15548110 | AH6: 14978563 | AI6: 17678212 | AJ6: 19991942 | AK6: 2.0790156e+08 | AL6: 1.0826759e+08 | AM6: 99633973 | AN6: 57830698 | AO6: 50436894 | AP6: 46985256 | AQ6: 52648718
A7: 26年口径 | B7: 数据库营销 | C7: 11875837 | D7: 9505244.6 | E7: 8448582.2 | F7: 10411125 | G7: 7751860 | H7: 8753480.6 | I7: 9067021.2 | J7: 7495744.8 | K7: 13999988 | L7: 18029060 | M7: 16780507 | N7: 8632591.5 | O7: 1.3075104e+08 | P7: 56746130 | Q7: 74004912 | R7: 29829664 | S7: 26916466 | T7: 30562754 | U7: 43442158 | W7: 26年口径 | X7: 数据库营销 | Y7: 2549751.2 | Z7: 1880081.8 | AA7: 2130051.2 | AB7: 2615080.4 | AC7: 1752152.4 | AD7: 2225886 | AE7: 1876419.1 | AF7: 1908652.7 | AG7: 2008057.6 | AH7: 1945294.6 | AI7: 3494718 | AJ7: 2180017.1 | AK7: 26566162 | AL7: 13153003 | AM7: 13413159 | AN7: 6559884.2 | AO7: 6593118.8 | AP7: 5793129.4 | AQ7: 7620029.7
A8: 26年口径 | B8: 私域 | C8: 5280469.7 | D8: 5228202.1 | E8: 5686460.7 | F8: 4949084.3 | G8: 4623575.5 | H8: 4963729.5 | I8: 5789922.8 | J8: 7084063.3 | K8: 5517952.4 | L8: 6676835 | M8: 5965314.6 | N8: 7951606.3 | O8: 69717216 | P8: 30731522 | Q8: 38985694 | R8: 16195133 | S8: 14536389 | T8: 18391938 | U8: 20593756 | W8: 26年口径 | X8: 私域 | Y8: 573137.28 | Z8: 613994.73 | AA8: 694290.26 | AB8: 571341.18 | AC8: 565277.8 | AD8: 628136.96 | AE8: 728343.65 | AF8: 803735.23 | AG8: 605885.04 | AH8: 791985.12 | AI8: 680080.68 | AJ8: 799188.63 | AK8: 8055396.6 | AL8: 3646178.2 | AM8: 4409218.3 | AN8: 1881422.3 | AO8: 1764755.9 | AP8: 2137963.9 | AQ8: 2271254.4
B9: 电视及APP-电视商品（含自营业务） | C9: 91060796 | D9: 71242893 | E9: 72887479 | F9: 72173433 | G9: 69886466 | H9: 65714355 | I9: 68868780 | J9: 65116614 | K9: 71528972 | L9: 79916867 | M9: 73733516 | N9: 68166470 | O9: 8.7029664e+08 | P9: 4.4296542e+08 | Q9: 4.2733122e+08 | R9: 2.3519117e+08 | S9: 2.0777425e+08 | T9: 2.0551437e+08 | U9: 2.2181685e+08 | X9: 电视及APP-电视商品（含自营业务） | Y9: 23141348 | Z9: 16740906 | AA9: 18651063 | AB9: 18127100 | AC9: 17050642 | AD9: 17242451 | AE9: 17060422 | AF9: 16235447 | AG9: 16150202 | AH9: 15755887 | AI9: 19418912 | AJ9: 18386453 | AK9: 2.1396083e+08 | AL9: 1.1095351e+08 | AM9: 1.0300732e+08 | AN9: 58533318 | AO9: 52420192 | AP9: 49446071 | AQ9: 53561252
B10: 电视及APP-电商商品 | C10: 16752497 | D10: 10504730 | E10: 11604644 | F10: 12473111 | G10: 13588685 | H10: 12776572 | I10: 11834622 | J10: 9796971.8 | K10: 11622005 | L10: 10625909 | M10: 15294616 | N10: 14523050 | O10: 1.5139741e+08 | P10: 77700239 | Q10: 73697173 | R10: 38861871 | S10: 38838368 | T10: 33253598 | U10: 40443575 | X10: 电视及APP-电商商品 | Y10: 2769275.6 | Z10: 1936495.7 | AA10: 2247014.9 | AB10: 2050038.4 | AC10: 1739691.9 | AD10: 1876888.2 | AE10: 1558920 | AF10: 1430264.5 | AG10: 1787154.4 | AH10: 1736339.4 | AI10: 2199376.9 | AJ10: 4376535.8 | AK10: 25707996 | AL10: 12619405 | AM10: 13088591 | AN10: 6952786.2 | AO10: 5666618.5 | AP10: 4776338.9 | AQ10: 8312252.1
B15: 26年销售目标 | X15: 26年利润目标
B16: 销售金额 | C16: 1月 | D16: 2月 | E16: 3月 | F16: 4月 | G16: 5月 | H16: 6月 | I16: 7月 | J16: 8月 | K16: 9月 | L16: 10月 | M16: 11月 | N16: 12月 | O16: 合计 | P16: H1 | Q16: H2 | R16: Q1 | S16: Q2 | T16: Q3 | U16: Q4 | X16: 利润金额 | Y16: 1月 | Z16: 2月 | AA16: 3月 | AB16: 4月 | AC16: 5月 | AD16: 6月 | AE16: 7月 | AF16: 8月 | AG16: 9月 | AH16: 10月 | AI16: 11月 | AJ16: 12月 | AK16: 合计 | AL16: H1 | AM16: H2 | AN16: Q1 | AO16: Q2 | AP16: Q3 | AQ16: Q4
B17: 存量整体 | C17: 99061446 | D17: 71731576 | E17: 79220420 | F17: 81951908 | G17: 78847804 | H17: 75920356 | I17: 77009398 | J17: 73330395 | K17: 74938092 | L17: 77288871 | M17: 83121007 | N17: 79375529 | O17: 9.517968e+08 | P17: 4.8673351e+08 | Q17: 4.6506329e+08 | R17: 2.5001344e+08 | S17: 2.3672007e+08 | T17: 2.2527788e+08 | U17: 2.3978541e+08 | X17: 存量整体 | Y17: 23226681 | Z17: 16184643 | AA17: 18883028 | AB17: 18605316 | AC17: 17245454 | AD17: 17507669 | AE17: 17209969 | AF17: 16413118 | AG17: 16708599 | AH17: 16115526 | AI17: 19654694 | AJ17: 19852334 | AK17: 2.1760703e+08 | AL17: 1.1165279e+08 | AM17: 1.0595424e+08 | AN17: 58294352 | AO17: 53358439 | AP17: 50331686 | AQ17: 55622554
A18: 26年口径 | B18: 仅电视端及APP业务 （含自营业务） | C18: 78968729 | D18: 58442847 | E18: 61657160 | F18: 60719897 | G18: 62077814 | H18: 56610227 | I18: 57583160 | J18: 52901146 | K18: 55680594 | L18: 57502763 | M18: 58008239 | N18: 57929538 | O18: 7.1808211e+08 | P18: 3.7847667e+08 | Q18: 3.3960544e+08 | R18: 1.9906874e+08 | S18: 1.7940794e+08 | T18: 1.661649e+08 | U18: 1.7344054e+08 | W18: 26年口径 | X18: 仅电视端及APP业务 （含自营业务） | Y18: 19601681 | Z18: 13951219 | AA18: 15859315 | AB18: 14891718 | AC18: 14441552 | AD18: 14253253 | AE18: 14045318 | AF18: 13127913 | AG18: 13439765 | AH18: 12949109 | AI18: 15267218 | AJ18: 16278970 | AK18: 1.7810703e+08 | AL18: 92998738 | AM18: 85108292 | AN18: 49412216 | AO18: 43586523 | AP18: 40612995 | AQ18: 44495298
A19: 26年口径 | B19: 数据库营销 | C19: 13874286 | D19: 7789072.9 | E19: 10709975 | F19: 13630878 | G19: 9249524.1 | H19: 10953384 | I19: 9736341.1 | J19: 9736341.1 | K19: 11196792 | L19: 9249524.1 | M19: 16064963 | N19: 11683609 | O19: 1.3387469e+08 | P19: 66207120 | Q19: 67667571 | R19: 32373334 | S19: 33833785 | T19: 30669474 | U19: 36998096 | W19: 26年口径 | X19: 数据库营销 | Y19: 2850000 | Z19: 1600000 | AA19: 2200000 | AB19: 2800000 | AC19: 1900000 | AD19: 2250000 | AE19: 2000000 | AF19: 2000000 | AG19: 2300000 | AH19: 1900000 | AI19: 3300000 | AJ19: 2400000 | AK19: 27500000 | AL19: 13600000 | AM19: 13900000 | AN19: 6650000 | AO19: 6950000 | AP19: 6300000 | AQ19: 7600000
A20: 26年口径 | B20: 私域 | C20: 6218431.4 | D20: 5499656 | E20: 6853285 | F20: 7601133.4 | G20: 7520466.1 | H20: 8356745.5 | I20: 9689897.1 | J20: 10692908 | K20: 8060705.5 | L20: 10536584 | M20: 9047805.7 | N20: 9762382 | O20: 99840000 | P20: 42049717 | Q20: 57790283 | R20: 18571372 | S20: 23478345 | T20: 28443511 | U20: 29346772 | W20: 26年口径 | X20: 私域 | Y20: 775000 | Z20: 633423.97 | AA20: 823712.13 | AB20: 913597.76 | AC20: 903902.17 | AD20: 1004416.5 | AE20: 1164651.1 | AF20: 1285205.3 | AG20: 968834.8 | AH20: 1266416.4 | AI20: 1087476.6 | AJ20: 1173363.2 | AK20: 12000000 | AL20: 5054052.6 | AM20: 6945947.4 | AN20: 2232136.1 | AO20: 2821916.5 | AP20: 3418691.2 | AQ20: 3527256.3
B21: 电视及APP-电视商品（含自营业务） | C21: =Y21*1.12/0.275 -> 85136343 | D21: =Z21*1.12/0.275 -> 59324074 | E21: =AA21*1.12/0.275 -> 69214879 | F21: =AB21*1.12/0.275 -> 68196939 | G21: =AC21*1.12/0.275 -> 63212428 | H21: =AD21*1.12/0.275 -> 64173566 | I21: =AE21*1.12/0.275 -> 63082358 | J21: =AF21*1.12/0.275 -> 60161538 | ... N21: =AJ21*1.12/0.275 -> 72767827 | O21: =SUM(C21:N21) -> 7.9762868e+08 | P21: =SUM(C21:H21) -> 4.0925823e+08 | Q21: =SUM(I21:N21) -> 3.8837045e+08 | R21: =SUM(C21:E21) -> 2.136753e+08 | S21: =SUM(F21:H21) -> 1.9558293e+08 | T21: =SUM(I21:K21) -> 1.8448851e+08 | U21: =SUM(L21:N21) -> 2.0388194e+08 | X21: 电视及APP-电视商品（含自营业务） | Y21: 20904013 | Z21: 14566179 | AA21: 16994725 | AB21: 16744784 | AC21: 15520909 | AD21: 15756902 | AE21: 15488972 | AF21: 14771806 | AG21: 15037739 | AH21: 14503973 | AI21: 17689225 | AJ21: 17867100 | AK21: 1.9584633e+08 | AL21: 1.0048751e+08 | AM21: 95358816 | AN21: 52464916 | AO21: 48022595 | AP21: 45298517 | AQ21: 50060298
